Workbook
Name rate_commercial: 'Inputs'!$B$6
Name rate_public: 'Inputs'!$B$7
Name years: 'Inputs'!$B$8
Name eur_gbp: 'Inputs'!$B$9
Name price_cucumber: 'Inputs'!$B$11
Name commission: 'Inputs'!$B$12
Name import_parity: 'Inputs'!$B$13
Name labour_rate: 'Inputs'!$B$15
Name labour_h_m2: 'Inputs'!$B$16
Name co2_price: 'Inputs'!$B$17
Name plants_m2: 'Inputs'!$B$18
Name substrate_m2: 'Inputs'!$B$19
Name materials_m2: 'Inputs'!$B$20
Name pack_gbp_kg: 'Inputs'!$B$21
Name om_frac: 'Inputs'!$B$22
Name overheads_m2: 'Inputs'!$B$23
Name land_rent_ha: 'Inputs'!$B$24
Name land_extra: 'Inputs'!$B$25
Name dev_frac: 'Inputs'!$B$27
Name contingency: 'Inputs'!$B$28
Name hv_conn: 'Inputs'!$B$29
Name r_steel: 'Rates'!$D$6
Name life_steel: 'Rates'!$F$6
Name r_aluminium: 'Rates'!$D$7
Name life_aluminium: 'Rates'!$F$7
Name r_glass_single_m2: 'Rates'!$D$8
Name life_glass_single_m2: 'Rates'!$F$8
Name r_glass_dbl_ar_m2: 'Rates'!$D$9
Name life_glass_dbl_ar_m2: 'Rates'!$F$9
Name r_glass_dbl_lowe_m2: 'Rates'!$D$10
Name life_glass_dbl_lowe_m2: 'Rates'!$F$10
Name r_concrete: 'Rates'!$D$11
Name life_concrete: 'Rates'!$F$11
Name r_heating_pipe_m: 'Rates'!$D$12
Name life_heating_pipe_m: 'Rates'!$F$12
Name r_energy_screen_m2: 'Rates'!$D$13
Name life_energy_screen_m2: 'Rates'!$F$13
Name r_resid: 'Rates'!$D$14
Name life_resid: 'Rates'!$F$14
Name dea_hp_1: 'Rates'!$C$17
Name dea_hp_3: 'Rates'!$D$17
Name dea_hp_10: 'Rates'!$E$17
Name life_hp: 'Rates'!$F$17
Name om_hp: 'Rates'!$D$18
Name r_boiler: 'Rates'!$D$19
Name life_boiler: 'Rates'!$F$19
Name om_boiler: 'Rates'!$D$20
Name r_store: 'Rates'!$D$21
Name life_store: 'Rates'!$F$21
Name om_store: 'Rates'!$D$22
Name turb_kw: 'Rates'!$D$25
Name turb_gbp_kw: 'Rates'!$D$26
Name turb_conn: 'Rates'!$D$27
Name turb_om_kw: 'Rates'!$D$28
Name turb_gen: 'Rates'!$D$29
Name turb_life: 'Rates'!$D$30
Name export_price: 'Rates'!$D$31
Name pw_price: 'Rates'!$D$32
Name pw_capex: 'Rates'!$D$33
Name fixed_resid_share: 'Scale'!$B$4

Sheet Read Me
A1: Glasshouse capex / opex model: track B lead design (1 ha cucumber, Scotland)
A2: Built 2026-10-05 by lca/bplan_workbook.py from the verified BEng-CEA-Heatpump/lca model. Edit blue cells.
A4: What this is
B5: Every capital and running cost of the lead glasshouse design, item by item, for five design scenarios side by side, so you can see where the money goes and test ways to cut the initial spend.
B6: Results are computed live: change a blue input or a unit rate and every total, £/kg and NPV updates.
A7: How to use
B8: 1. 'Inputs': discount rates, prices, labour rate, commission and other global assumptions.
B9: 2. 'Rates': unit costs (£/t steel, £/m² glass, £/kW heat pump ...). Try supplier quotes here.
B10: 3. 'Scenarios': the physical design of each option (areas, quantities, kW, MWh, yield) from the simulation.
B11: 4. 'Capex': initial expenditure by item and by cost driver (per m², per kW, fixed). 'Opex': annual costs.
B12: 5. 'Results': initial spend, cost per kg, margin and NPV at 8 % (commercial) and 3.5 % (Green Book).
B13: 6. 'Scale': how cost per m² changes with greenhouse size when fixed costs are separated from per-m² costs.
B14: 7. 'Capex Levers': every capex-reduction idea, its status, evidence and next step.
A15: Colour code
B16: Blue text = input you can change. Black = formula. Green = link to another sheet. Yellow fill = key assumption. Grey fill = totals.
A17: Scenarios
B18: S0: Today: double AR glass, heat pump 69 % + 4.2 MWh store, owned 2.5 MW turbine
B19: S1: Double AR glass, LP-sized heat pump + peak boiler + store, owned turbine
B20: S2: Single glass, LP-sized heat pump + peak boiler + store, owned turbine
B21: S3: Single glass, LP-sized heat pump + peak boiler + store, private-wire PPA (no turbine)
B22: S4: Double AR glass, LP-sized heat pump + peak boiler + store, private-wire PPA (no turbine)
A23: Boundaries and basis
B24: Cost boundary: farm gate to the supermarket regional distribution centre (RDC): growing, packing and haulage to the RDC are included; RDC-to-shelf is not (soil-to-shelf ledger is task BP15).
B25: Price: DEFRA UK wholesale (weekly averages, 2023-26) weighted by the harvest month, less 14 % market commission (user decision 2026-10-05). Contract prices are not assumed to carry a premium.
B26: Levelised costs use equivalent annual cost per item (capex x capital recovery factor at the item's life). NPV = (revenue - running costs - equivalent annual capital costs) x 30-year annuity factor. This is a steady-state shortcut: it omits the 80 % ramp-up year and the residual value that cashflow.py includes (the 'Results' sheet shows the check against cashflow.py).
B27: The owned 2.5 MW turbine is a separate business: the greenhouse buys its power at the turbine's levelised cost, computed here at each discount rate. Its capex is reported as 'energy route' initial spend, not in the greenhouse cost per kg.
A28: Status
B29: Concept stage (Gate B). About 46 % of structure items are supplier placeholders (RFQ_SPEC.md). Yields are model results (0.89-1.03 x the Dutch average) awaiting UK evidence. See the 'Sources' sheet.

Sheet Inputs
A1: Global inputs
A2: Blue = editable. Tier: sourced / standard / model / estimate / placeholder.
A4: Input | B4: Value | C4: Unit | D4: Tier | E4: Source / note
A5: Finance
A6: Discount rate, commercial (headline) | B6: 0.08 | C6: /yr real | D6: choice | E6: Investor/bank basis (user decision 2026-10-05)
A7: Discount rate, public (Green Book) | B7: 0.035 | C7: /yr real | D7: standard | E7: HM Treasury Green Book (2022) Annex 6: 3.5 % years 0-30
A8: Study period | B8: 30 | C8: yr | D8: standard | E8: SCOPE §2; Green Book appraisal period
A9: EUR to GBP | B9: 0.8567 | C9: GBP/EUR | D9: sourced | E9: ECB reference rates via api.frankfurter.dev, 2025 mean
A10: Sales
A11: Cucumber price, harvest-weighted (link to 'Prices') | B11: ='Prices'!$D$17 | C11: GBP/kg | D11: sourced | E11: DEFRA wholesale fruit and vegetable prices, weekly average, 2023-26, months with < 3 UK observations use the UK import CIF price (Comtrade 2023-25). https://www.gov.uk/government/statistical-data-sets/wholesale-fruit-and-vegetable-prices-weekly-average
A12: Market commission (wholesale route) | B12: 0.14 | C12: of revenue | D12: sourced (secondary) | E12: BritFarmers, T. Harfield, 'UK supermarket contracts vs wholesale pricing 2026' (trade guide, June 2026): 14 % commission plus transport. Was 5 % placeholder in cashflow.py
A13: Import parity price at the RDC (reference only) | B13: 1.574 | C13: GBP/kg | D13: sourced | E13: Comtrade CIF 2023-25 at the UK border + port-to-RDC haul (site_rank.py). Excludes port fees, border checks, importer margin (BP15)
A14: Operations
A15: Labour rate incl. on-costs | B15: 15 | C15: GBP/h | D15: estimate | E15: UK National Living Wage £12.21/h (Apr 2025) + ~20 % on-costs (input_register: pending)
A16: Labour per m² growing area | B16: 0.8 | C16: h/m²/yr | D16: estimate | E16: Glasshouse fruit veg 0.75-1.0 h/m²/yr; KWIN/AHDB to source. Flat per m² with scale (RaboResearch 2025 fig. 6: Dutch m² per work unit stable)
A17: CO2 (bulk liquid, delivered) | B17: 0.25 | C17: GBP/kg | D17: sourced (secondary) | E17: breakeven.py; distillery fermentation CO2 could be ~free (lever)
A18: Young plants | B18: 3.5 | C18: GBP/m²/yr | D18: sourced (range) | E18: cashflow.py: three crops/yr; tomato GBP 1.61-6.4/m² range (J. Cleaner Prod. 2022; KWIN 2023)
A19: Substrate | B19: 0.75 | C19: GBP/m²/yr | D19: sourced | E19: KWIN 2023 growing media EUR 0.86/m²
A20: Fertiliser, crop protection, strings, water | B20: 2 | C20: GBP/m²/yr | D20: sourced (secondary) | E20: J. Cleaner Production 2022 UK tomato GBP 2.27-2.48/m²; cucumber without bumblebees
A21: Packing | B21: 0.1 | C21: GBP/kg | D21: estimate | E21: Packhouse, film, carton (crops.py); to source
A22: Structure O&M + insurance | B22: 0.02 | C22: of structure capex /yr | D22: estimate | E22: breakeven.py
A23: Overheads (management, certification, accounts) | B23: 3 | C23: GBP/m²/yr | D23: placeholder | E23: No UK source; BritFarmers 2026 puts retailer compliance at £8-50k/yr, inside this
A24: Land rent | B24: 1000 | C24: GBP/ha/yr | D24: placeholder | E24: Scottish arable ~£250-500/ha; industrial land more
A25: Extra land for access, packhouse, plant | B25: 0.3 | C25: of glass area | D25: estimate | E25: cashflow.py
A26: Project
A27: Development (design, planning, legal, site investigation) | B27: 0.05 | C27: of capex | D27: estimate | E27: Feasibility-stage allowance
A28: Contingency | B28: 0.1 | C28: of capex | D28: estimate | E28: Class 4 estimate (±30 %)
A29: HV import connection (11 kV) | B29: 150000 | C29: GBP | D29: sourced (range) | E29: £50-150k near a substation (solargridcheck.co.uk G99 guide 2026); upper end. Should scale with kVA (BP16)

Sheet Rates
A1: Unit rates
A2: Central rate drives the model; low/high are the quote range. Replace with supplier quotes.
A4: Item | B4: Unit | C4: Low | D4: Central | E4: High | F4: Life (yr) | G4: Cost driver | H4: Tier | I4: Source
A5: Structure (quantities x rate)
A6: Steel frame, erected | B6: t | D6: 4890 | F6: 30 | G6: per t (from frame sizing) | H6: industry cost model | I6: BCIS frame cost model via SteelConstruction.info 'Cost of structural steelwork': GBP 158-191/m2 GIFA at 55 kg/m2 steel (index 100) x BCIS steel index Q1 2025 154.2 -> GBP/t erected
A7: Aluminium glazing bars | B7: kg | C7: 4 | D7: 6 | E7: 9 | F7: 30 | G7: per kg (per m of bar) | H7: needs quote (placeholder) | I7: Glazing bars / cushion extrusions; no public project-scale price found. Placeholder range 4-9 GBP/kg
A8: Glass, single 4 mm 2xAR | B8: m² | C8: 15 | D8: 25 | E8: 40 | F8: 30 | G8: per m² glazed | H8: needs quote (placeholder) | I8: 4 mm toughened 2xAR horticultural glass; public prices are retail panes (~GBP 70/m2), not project scale. Placeholder range 15-40
A9: Glass, double AR sealed unit | B9: m² | C9: 45 | D9: 65 | E9: 100 | F9: 30 | G9: per m² glazed | H9: needs quote (placeholder) | I9: Double AR sealed unit; placeholder range 45-100
A10: Glass, double AR + low-e | B10: m² | C10: 50 | D10: 75 | E10: 120 | F10: 30 | G10: per m² glazed | H10: needs quote (placeholder) | I10: Double AR + low-e sealed unit for Venlo; no public price. Placeholder range 50-120
A11: Concrete (pads, edge beam, paths) | B11: m³ | D11: 102 | F11: 50 | G11: per m³ | H11: trade price | I11: Scotland ready-mix RC30/C30/37 GBP 90-115/m3 (mixdesigncalc.co.uk trade price guide, 2025-26)
A12: Heating pipe-rail (51 mm) | B12: m | D12: 8 | F12: 30 | G12: per m (2.25 m per m²) | H12: needs quote (placeholder) | I12: 51 x 2.0 mm steel pipe-rail; placeholder
A13: Energy screen incl. drive | B13: m² | D13: 6 | F13: 10 | G13: per m² floor | H13: needs quote (placeholder) | I13: Energy screen cloth incl. drive; placeholder
A14: Installation, climate computer, irrigation, vents, wires, design (residual) | B14: m² | D14: 94.4 | F14: 30 | G14: per m² floor (see 'Scale') | H14: calibrated | I14: SAC/SRUC (2026) 'Developing SME-scale CEA' Table 11: commercial glasshouse £2M/ha minus the itemised list for a 1 ha Venlo reference (costing.py). Not itemised: the biggest single capex item, the first target for an itemised RFQ.
A16: Heat system
A17: Heat pump (R717, air source), DEA cost curve | B17: MEUR/MW at 1 / 3 / 10 MW | C17: 1.15 | D17: 1.1 | E17: 1.02 | F17: 25 | G17: per kW, log-interpolated by size | H17: sourced | I17: Danish Energy Agency, Technology Data for Generation of Electricity and District Heating, ch. 40 'Comp. hp, airsource 1/3/10 MW', Aug 2026 data sheets, total investment (2030 column used by site_opt.py). Note P: +15 % for 40-80 °C supply temperatures (not applied)
A18: Heat pump fixed O&M | B18: EUR/MW/yr | D18: 2126.745 | H18: sourced | I18: DEA ch. 40 airsource 1 MW, fixed O&M
A19: Electric peak boiler | B19: MEUR/MW | D19: 0.15457 | F19: 25 | G19: per kW | H19: sourced | I19: DEA ch. 41 'Electric boiler, small': total investment 0.155 MEUR/MW (equipment 0.087 + installation 0.067), efficiency 0.99. About 7x cheaper per kW than the heat pump: the cheap way to cover the few peak hours (Stanghellini et al. 2019/2023, Greenhouse Horticulture, §8.9 eq. 8.14 and fig. 8.14)
A20: Electric boiler fixed O&M | B20: EUR/MW/yr | D20: 1137.8 | H20: sourced | I20: DEA ch. 41
A21: Hot-water store (buffer tank) | B21: GBP/kWh stored | D21: 26.44 | F21: 40 | G21: per kWh capacity | H21: sourced | I21: DEA Technology Data for Energy Storage, hot-water tank, at 4.2 MWh (finalist_lp.py; size-dependent). Buffer lowers peak plant: Stanghellini et al. §8.8 (25 W/m² store + 50 W/m² boiler = 75 W/m²)
A22: Hot-water store O&M | B22: EUR2015/MWh/yr | D22: 8.6 | H22: sourced | I22: DEA storage; x1.2876 to 2025 EUR (finalist_lp.py)
A24: Energy route
A25: Owned turbine size | B25: kW | D25: 2500 | I25: Single 2.5 MW turbine (energy_grid own_2p5MW)
A26: Turbine capex | B26: GBP/kW | D26: 2240 | I26: Kilbirnie 2.5 MW community turbine, N. Ayrshire, £5.6M (Envirotec, 5 Mar 2026)
A27: Turbine export connection allowance | B27: GBP | D27: 300000 | I27: 33 kV £0.3-1.0M, 11 kV £50-150k (solargridcheck.co.uk 2026)
A28: Turbine O&M | B28: GBP/kW/yr | D28: 21.06 | I28: Arup (2025) for DESNZ, Table 18: £19.5k/MW/a (2023 £) x1.08
A29: Turbine generation | B29: MWh/yr | D29: 9044.7 | I29: Model: Global Wind Atlas at the site, capacity factor capped at 41.3 % (Arup 2025 Table 22)
A30: Turbine life (repowered once in 30 yr) | B30: yr | D30: 20 | I30: Arup (2025)
A31: Export PPA price for surplus | B31: GBP/MWh | D31: 60 | I31: ~£70/MWh fair value (Veyt 2025) less ~£10 route-to-market (estimate)
A32: Private-wire PPA price | B32: GBP/MWh | D32: 90 | I32: Savills 2025: £80-120/MWh delivered; low end (energy_grid private_wire). Needs a wind farm within a few km (Girvan: 16 large turbines within 3.1 km)
A33: Private-wire connection capex (if paid by us) | B33: GBP | D33: 0 | I33: Not costed in the model (placeholder 0); typically a few £100k per km

Sheet Scenarios
A1: Design scenarios: physical quantities from the simulation
A2: Blue values are model outputs (site_opt.evaluate, track B lead design, Stranraer location, 2023 weather).
A4: Quantity | B4: Unit | C4: S0 | D4: S1 | E4: S2 | F4: S3 | G4: S4 | H4: Note
A5: Description | C5: Today: double AR glass, heat pump 69 % + 4.2 MWh store, owned 2.5 MW turbine | D5: Double AR glass, LP-sized heat pump + peak boiler + store, owned turbine | E5: Single glass, LP-sized heat pump + peak boiler + store, owned turbine | F5: Single glass, LP-sized heat pump + peak boiler + store, private-wire PPA (no turbine) | G5: Double AR glass, LP-sized heat pump + peak boiler + store, private-wire PPA (no turbine)
A6: Design
A7: Glazing | B7: - | C7: Double AR | D7: Double AR | E7: Single 2xAR | F7: Single 2xAR | G7: Double AR
A8: Owns the 2.5 MW turbine (1 = yes) | B8: flag | C8: 1 | D8: 1 | E8: 1 | F8: 0 | G8: 0
A9: Glasshouse floor area | B9: m² | C9: 10000 | D9: 10000 | E9: 10000 | F9: 10000 | G9: 10000 | H9: 4 spans x 15.4 m x 162 m, gutter 4.64 m
A10: Growing share of floor (paths excluded) | B10: - | C10: 0.94 | D10: 0.94 | E10: 0.94 | F10: 0.94 | G10: 0.94
A11: Perimeter | B11: m | C11: 447.56339 | D11: 447.56339 | E11: 447.56339 | F11: 447.56339 | G11: 447.56339
A12: Glazed area (roof + walls) | B12: m² | C12: 12343.195 | D12: 12343.195 | E12: 12343.195 | F12: 12343.195 | G12: 12343.195
A13: Bill of quantities (costing.bill)
A14: Steel | B14: t | C14: 68.303823 | D14: 68.303823 | E14: 64.05158 | F14: 64.05158 | G14: 68.303823 | H14: Concept frame sizing (sizing.py, EN 13031-1 loads)
A15: Aluminium | B15: kg | C15: 15799.289 | D15: 15799.289 | E15: 11849.467 | F15: 11849.467 | G15: 15799.289
A16: Glass | B16: m² | C16: 12343.195 | D16: 12343.195 | E16: 12343.195 | F16: 12343.195 | G16: 12343.195
A17: Concrete | B17: m³ | C17: 299.92456 | D17: 299.92456 | E17: 289.32795 | F17: 289.32795 | G17: 299.92456
A18: Heating pipe | B18: m | C18: 22500 | D18: 22500 | E18: 22500 | F18: 22500 | G18: 22500
A19: Energy screen | B19: m² | C19: 10000 | D19: 10000 | E19: 10000 | F19: 10000 | G19: 10000
A20: Heat system
A21: Design heat load (-3.1 °C outside) | B21: kW | C21: 1245.5516 | D21: 1245.5516 | E21: 2186.4733 | F21: 2186.4733 | G21: 1245.5516 | H21: Single glass loses ~75 % more heat
A22: Heat pump capacity | B22: kW | C22: 856.5412 | D22: 457.12 | E22: 765.43882 | F22: 836.95858 | G22: 508.94508 | H22: S0: LP-sized, floored to meet the 2010 winter with the store
A23: Electric peak boiler | B23: kW | C23: 0 | D23: 788.43158 | E23: 1421.0345 | F23: 1349.5147 | G23: 736.60649 | H23: LP-sized with the heat pump and store (BP19a); boiler + heat pump = design load, so it is also the standby
A24: Hot-water store | B24: kWh | C24: 4171.7381 | D24: 4182.1382 | E24: 13313.687 | F24: 11974.982 | G24: 4079.319 | H24: LP-sized in every scenario (BP19a re-ran S1-S4 with the store)
A25: Heat delivered | B25: MWh/yr | C25: 2838.4136 | D25: 2838.4136 | E25: 4940.4202 | F25: 4940.4202 | G25: 2838.4136
A26: of which from the boiler | B26: MWh/yr | C26: 0 | D26: 98.804635 | E26: 180.50312 | F26: 66.114317 | G26: 41.586131
A27: Electricity
A28: Electricity use (heat pump, boiler, fans, pumps) | B28: MWh/yr | C28: 998.73285 | D28: 965.71157 | E28: 1674.2819 | F28: 1594.5167 | G28: 921.07013
A29: Share met by wind (own turbine or private wire) | B29: - | C29: 0.88722722 | D29: 0.95136849 | E29: 0.93417652 | F29: 0.9216625 | G29: 0.93065175 | H29: Hourly dispatch (energy_grid.py)
A30: Grid top-up price (delivered, all charges) | B30: GBP/MWh | C30: 177.09273 | D30: 178.19224 | E30: 178.17665 | F30: 178.17665 | G30: 178.19224 | H30: DESNZ business price, wholesale share on the Agile shape
A31: Network charge increase (peak import band) | B31: GBP/yr | C31: 19837.75 | D31: 19837.75 | E31: 23221.3 | F31: 23221.3 | G31: 19837.75 | H31: NESO TNUoS 2026/27 bands; jumps with peak kVA
A32: Crop
A33: Yield per m² floor | B33: kg/m²/yr | C33: 54.606662 | D33: 54.606662 | E33: 62.020361 | F33: 62.020361 | G33: 54.606662 | H33: crop_gh, calibrated to CBS NL; single glass +14 % from more light (elasticity ~1)
A34: CO2 dosed | B34: kg/m²/yr | C34: 34.251805 | D34: 34.251805 | E34: 33.115794 | F34: 33.115794 | G34: 34.251805
A35: Haulage to RDCs | B35: GBP/kg | C35: 0.046082055 | D35: 0.046082055 | E35: 0.046082055 | F35: 0.046082055 | G35: 0.046082055 | H35: Stranraer 165 km; Girvan would be £0.032/kg
A36: Carbon delivered to RDC | B36: kg CO2e/kg | C36: 0.29987591 | D36: 0.33527125 | E36: 0.40541686 | F36: 0.32390648 | G36: 0.30446586 | H36: Imports 0.81

Sheet Capex
A1: Initial expenditure by item (GBP)
A2: Quantity (Scenarios) x unit rate (Rates). Grey rows are totals.
A4: Item | B4: Cost driver | C4: S0 | D4: S1 | E4: S2 | F4: S3 | G4: S4 | H4: Life (yr) | I4: Note
A5: Structure
A6: Steel frame | B6: per t | C6: ='Scenarios'!C14*r_steel | D6: ='Scenarios'!D14*r_steel | E6: ='Scenarios'!E14*r_steel | F6: ='Scenarios'!F14*r_steel | G6: ='Scenarios'!G14*r_steel | H6: =life_steel
A7: Aluminium glazing bars | B7: per kg | C7: ='Scenarios'!C15*r_aluminium | D7: ='Scenarios'!D15*r_aluminium | E7: ='Scenarios'!E15*r_aluminium | F7: ='Scenarios'!F15*r_aluminium | G7: ='Scenarios'!G15*r_aluminium | H7: =life_aluminium
A8: Glass | B8: per m² glazed | C8: =IF('Scenarios'!C7="Double AR",r_glass_dbl_ar_m2,r_glass_single_m2)*'Scenarios'!C16 | D8: =IF('Scenarios'!D7="Double AR",r_glass_dbl_ar_m2,r_glass_single_m2)*'Scenarios'!D16 | E8: =IF('Scenarios'!E7="Double AR",r_glass_dbl_ar_m2,r_glass_single_m2)*'Scenarios'!E16 | F8: =IF('Scenarios'!F7="Double AR",r_glass_dbl_ar_m2,r_glass_single_m2)*'Scenarios'!F16 | G8: =IF('Scenarios'!G7="Double AR",r_glass_dbl_ar_m2,r_glass_single_m2)*'Scenarios'!G16 | H8: =life_glass_dbl_ar_m2 | I8: Rate switches with the glazing choice
A9: Concrete foundations and paths | B9: per m³ | C9: ='Scenarios'!C17*r_concrete | D9: ='Scenarios'!D17*r_concrete | E9: ='Scenarios'!E17*r_concrete | F9: ='Scenarios'!F17*r_concrete | G9: ='Scenarios'!G17*r_concrete | H9: =life_concrete
A10: Heating pipe-rail | B10: per m | C10: ='Scenarios'!C18*r_heating_pipe_m | D10: ='Scenarios'!D18*r_heating_pipe_m | E10: ='Scenarios'!E18*r_heating_pipe_m | F10: ='Scenarios'!F18*r_heating_pipe_m | G10: ='Scenarios'!G18*r_heating_pipe_m | H10: =life_heating_pipe_m
A11: Energy screen | B11: per m² floor | C11: ='Scenarios'!C19*r_energy_screen_m2 | D11: ='Scenarios'!D19*r_energy_screen_m2 | E11: ='Scenarios'!E19*r_energy_screen_m2 | F11: ='Scenarios'!F19*r_energy_screen_m2 | G11: ='Scenarios'!G19*r_energy_screen_m2 | H11: =life_energy_screen_m2 | I11: 10-yr life: replaced twice in 30 yr
A12: Installation, climate computer, irrigation, vents, wires (residual) | B12: per m² floor | C12: ='Scenarios'!C9*r_resid | D12: ='Scenarios'!D9*r_resid | E12: ='Scenarios'!E9*r_resid | F12: ='Scenarios'!F9*r_resid | G12: ='Scenarios'!G9*r_resid | H12: =life_resid | I12: SAC-calibrated lump: itemise with an RFQ
A13: Structure total | C13: =C6+C7+C8+C9+C10+C11+C12 | D13: =D6+D7+D8+D9+D10+D11+D12 | E13: =E6+E7+E8+E9+E10+E11+E12 | F13: =F6+F7+F8+F9+F10+F11+F12 | G13: =G6+G7+G8+G9+G10+G11+G12
A14: Heat system
A15: Heat pump | B15: per kW (DEA size curve) | C15: ='Scenarios'!C22*IF(('Scenarios'!C22/1000)<=1,dea_hp_1,IF(('Scenarios'!C22/1000)<=3,dea_hp_1+LN(('Scenarios'!C22/1000))/LN(3)*(dea_hp_3-dea_hp_1),IF(('Scenarios'!C22/1000)<=10,dea_hp_3+LN(('Scenarios'!C22/1000)/3)/LN(10/3)*(dea_hp_10-dea_hp_3),dea_hp_10)))*1000*eur_gbp | D15: ='Scenarios'!D22*IF(('Scenarios'!D22/1000)<=1,dea_hp_1,IF(('Scenarios'!D22/1000)<=3,dea_hp_1+LN(('Scenarios'!D22/1000))/LN(3)*(dea_hp_3-dea_hp_1),IF(('Scenarios'!D22/1000)<=10,dea_hp_3+LN(('Scenarios'!D22/1000)/3)/LN(10/3)*(dea_hp_10-dea_hp_3),dea_hp_10)))*1000*eur_gbp | E15: ='Scenarios'!E22*IF(('Scenarios'!E22/1000)<=1,dea_hp_1,IF(('Scenarios'!E22/1000)<=3,dea_hp_1+LN(('Scenarios'!E22/1000))/LN(3)*(dea_hp_3-dea_hp_1),IF(('Scenarios'!E22/1000)<=10,dea_hp_3+LN(('Scenarios'!E22/1000)/3)/LN(10/3)*(dea_hp_10-dea_hp_3),dea_hp_10)))*1000*eur_gbp | F15: ='Scenarios'!F22*IF(('Scenarios'!F22/1000)<=1,dea_hp_1,IF(('Scenarios'!F22/1000)<=3,dea_hp_1+LN(('Scenarios'!F22/1000))/LN(3)*(dea_hp_3-dea_hp_1),IF(('Scenarios'!F22/1000)<=10,dea_hp_3+LN(('Scenarios'!F22/1000)/3)/LN(10/3)*(dea_hp_10-dea_hp_3),dea_hp_10)))*1000*eur_gbp | G15: ='Scenarios'!G22*IF(('Scenarios'!G22/1000)<=1,dea_hp_1,IF(('Scenarios'!G22/1000)<=3,dea_hp_1+LN(('Scenarios'!G22/1000))/LN(3)*(dea_hp_3-dea_hp_1),IF(('Scenarios'!G22/1000)<=10,dea_hp_3+LN(('Scenarios'!G22/1000)/3)/LN(10/3)*(dea_hp_10-dea_hp_3),dea_hp_10)))*1000*eur_gbp | H15: =life_hp
A16: Electric peak boiler | B16: per kW | C16: ='Scenarios'!C23*r_boiler*1000*eur_gbp | D16: ='Scenarios'!D23*r_boiler*1000*eur_gbp | E16: ='Scenarios'!E23*r_boiler*1000*eur_gbp | F16: ='Scenarios'!F23*r_boiler*1000*eur_gbp | G16: ='Scenarios'!G23*r_boiler*1000*eur_gbp | H16: =life_boiler
A17: Hot-water store | B17: per kWh | C17: ='Scenarios'!C24*r_store | D17: ='Scenarios'!D24*r_store | E17: ='Scenarios'!E24*r_store | F17: ='Scenarios'!F24*r_store | G17: ='Scenarios'!G24*r_store | H17: =life_store
A18: Heat system total | C18: =C15+C16+C17 | D18: =D15+D16+D17 | E18: =E15+E16+E17 | F18: =F15+F16+F17 | G18: =G15+G16+G17
A19: Site and connection
A20: HV import connection | B20: fixed per site | C20: =hv_conn | D20: =hv_conn | E20: =hv_conn | F20: =hv_conn | G20: =hv_conn | H20: 30 | I20: Fixed: does not grow with m²
A21: Project costs
A22: Development (design, planning, legal, SI) | B22: % of the above | C22: =dev_frac*(C13+C18+C20) | D22: =dev_frac*(D13+D18+D20) | E22: =dev_frac*(E13+E18+E20) | F22: =dev_frac*(F13+F18+F20) | G22: =dev_frac*(G13+G18+G20) | H22: 30
A23: Contingency | B23: % of the above | C23: =contingency*(C13+C18+C20) | D23: =contingency*(D13+D18+D20) | E23: =contingency*(E13+E18+E20) | F23: =contingency*(F13+F18+F20) | G23: =contingency*(G13+G18+G20) | H23: 30
A24: GREENHOUSE INITIAL EXPENDITURE | C24: =C13+C18+C20+C22+C23 | D24: =D13+D18+D20+D22+D23 | E24: =E13+E18+E20+E22+E23 | F24: =F13+F18+F20+F22+F23 | G24: =G13+G18+G20+G22+G23
A25: Energy route (separate business)
A26: Owned 2.5 MW turbine + export connection | B26: fixed (one turbine) | C26: ='Scenarios'!C8*(turb_kw*turb_gbp_kw+turb_conn) | D26: ='Scenarios'!D8*(turb_kw*turb_gbp_kw+turb_conn) | E26: ='Scenarios'!E8*(turb_kw*turb_gbp_kw+turb_conn) | F26: ='Scenarios'!F8*(turb_kw*turb_gbp_kw+turb_conn) | G26: ='Scenarios'!G8*(turb_kw*turb_gbp_kw+turb_conn) | H26: =turb_life | I26: Zero on the private-wire PPA route
A27: Private-wire connection (if ours) | B27: fixed | C27: =(1-'Scenarios'!C8)*pw_capex | D27: =(1-'Scenarios'!D8)*pw_capex | E27: =(1-'Scenarios'!E8)*pw_capex | F27: =(1-'Scenarios'!F8)*pw_capex | G27: =(1-'Scenarios'!G8)*pw_capex | H27: 30 | I27: Placeholder 0
A28: ENERGY-ROUTE INITIAL EXPENDITURE | C28: =C26+C27 | D28: =D26+D27 | E28: =E26+E27 | F28: =F26+F27 | G28: =G26+G27
A29: TOTAL DAY-ONE SPEND | C29: =C24+C28 | D29: =D24+D28 | E29: =E24+E28 | F29: =F24+F28 | G29: =G24+G28
A31: Per m² and by cost driver
A32: Greenhouse capex per m² | C32: =C24/'Scenarios'!C9 | D32: =D24/'Scenarios'!D9 | E32: =E24/'Scenarios'!E9 | F32: =F24/'Scenarios'!F9 | G32: =G24/'Scenarios'!G9
A33: Total day-one spend per m² | C33: =C29/'Scenarios'!C9 | D33: =D29/'Scenarios'!D9 | E33: =E29/'Scenarios'!E9 | F33: =F29/'Scenarios'!F9 | G33: =G29/'Scenarios'!G9
A34: per m² items (glass, frame, screen, pipe, residual) | C34: =(C6+C7+C8+C9+C10+C11+C12)/C24 | D34: =(D6+D7+D8+D9+D10+D11+D12)/D24 | E34: =(E6+E7+E8+E9+E10+E11+E12)/E24 | F34: =(F6+F7+F8+F9+F10+F11+F12)/F24 | G34: =(G6+G7+G8+G9+G10+G11+G12)/G24
A35: per kW items (heat pump, boiler, store) | C35: =(C15+C16+C17)/C24 | D35: =(D15+D16+D17)/D24 | E35: =(E15+E16+E17)/E24 | F35: =(F15+F16+F17)/F24 | G35: =(G15+G16+G17)/G24
A36: fixed items (HV connection) | C36: =(C20)/C24 | D36: =(D20)/D24 | E36: =(E20)/E24 | F36: =(F20)/F24 | G36: =(G20)/G24
A37: % add-ons (development, contingency) | C37: =(C22+C23)/C24 | D37: =(D22+D23)/D24 | E37: =(E22+E23)/E24 | F37: =(F22+F23)/F24 | G37: =(G22+G23)/G24
A38: Change in greenhouse capex vs S0 | C38: =C24-$C$24 | D38: =D24-$C$24 | E38: =E24-$C$24 | F38: =F24-$C$24 | G38: =G24-$C$24
A39: Change in total day-one spend vs S0 | C39: =C29-$C$29 | D39: =D29-$C$29 | E39: =E29-$C$29 | F39: =F29-$C$29 | G39: =G29-$C$29

Sheet Energy
A1: Electricity price paid by the greenhouse, and the turbine as its own business
A2: Turbine route: wind share at the turbine's levelised cost, the rest from the grid. PPA route: wind share at the PPA price.
A4: Item | B4: Unit | C4: S0 | D4: S1 | E4: S2 | F4: S3 | G4: S4 | H4: Note
A5: At the commercial discount rate
A6: Turbine levelised cost of energy (LCOE) | B6: GBP/MWh | C6: =((turb_kw*turb_gbp_kw+turb_conn)*rate_commercial/(1-(1+rate_commercial)^-turb_life)+turb_kw*turb_om_kw)/turb_gen | D6: =((turb_kw*turb_gbp_kw+turb_conn)*rate_commercial/(1-(1+rate_commercial)^-turb_life)+turb_kw*turb_om_kw)/turb_gen | E6: =((turb_kw*turb_gbp_kw+turb_conn)*rate_commercial/(1-(1+rate_commercial)^-turb_life)+turb_kw*turb_om_kw)/turb_gen | F6: =((turb_kw*turb_gbp_kw+turb_conn)*rate_commercial/(1-(1+rate_commercial)^-turb_life)+turb_kw*turb_om_kw)/turb_gen | G6: =((turb_kw*turb_gbp_kw+turb_conn)*rate_commercial/(1-(1+rate_commercial)^-turb_life)+turb_kw*turb_om_kw)/turb_gen | H6: capex x CRF(rate, 20 yr) + O&M, over generation
A7: Blended electricity price to the greenhouse | B7: GBP/MWh | C7: ='Scenarios'!C29*IF('Scenarios'!C8=1,C6,pw_price)+(1-'Scenarios'!C29)*'Scenarios'!C30 | D7: ='Scenarios'!D29*IF('Scenarios'!D8=1,D6,pw_price)+(1-'Scenarios'!D29)*'Scenarios'!D30 | E7: ='Scenarios'!E29*IF('Scenarios'!E8=1,E6,pw_price)+(1-'Scenarios'!E29)*'Scenarios'!E30 | F7: ='Scenarios'!F29*IF('Scenarios'!F8=1,F6,pw_price)+(1-'Scenarios'!F29)*'Scenarios'!F30 | G7: ='Scenarios'!G29*IF('Scenarios'!G8=1,G6,pw_price)+(1-'Scenarios'!G29)*'Scenarios'!G30 | H7: Model check at 3.5 %: S0 £66.6, S3 £99.5/MWh (hourly dispatch)
A8: Turbine business NPV (sales to greenhouse at LCOE + export) | B8: GBP | C8: ='Scenarios'!C8*('Scenarios'!C28*'Scenarios'!C29*C6+MAX(turb_gen-'Scenarios'!C28*'Scenarios'!C29,0)*export_price-turb_kw*turb_om_kw-(turb_kw*turb_gbp_kw+turb_conn)*rate_commercial/(1-(1+rate_commercial)^-turb_life))*((1-(1+rate_commercial)^-years)/rate_commercial) | D8: ='Scenarios'!D8*('Scenarios'!D28*'Scenarios'!D29*D6+MAX(turb_gen-'Scenarios'!D28*'Scenarios'!D29,0)*export_price-turb_kw*turb_om_kw-(turb_kw*turb_gbp_kw+turb_conn)*rate_commercial/(1-(1+rate_commercial)^-turb_life))*((1-(1+rate_commercial)^-years)/rate_commercial) | E8: ='Scenarios'!E8*('Scenarios'!E28*'Scenarios'!E29*E6+MAX(turb_gen-'Scenarios'!E28*'Scenarios'!E29,0)*export_price-turb_kw*turb_om_kw-(turb_kw*turb_gbp_kw+turb_conn)*rate_commercial/(1-(1+rate_commercial)^-turb_life))*((1-(1+rate_commercial)^-years)/rate_commercial) | F8: ='Scenarios'!F8*('Scenarios'!F28*'Scenarios'!F29*F6+MAX(turb_gen-'Scenarios'!F28*'Scenarios'!F29,0)*export_price-turb_kw*turb_om_kw-(turb_kw*turb_gbp_kw+turb_conn)*rate_commercial/(1-(1+rate_commercial)^-turb_life))*((1-(1+rate_commercial)^-years)/rate_commercial) | G8: ='Scenarios'!G8*('Scenarios'!G28*'Scenarios'!G29*G6+MAX(turb_gen-'Scenarios'!G28*'Scenarios'!G29,0)*export_price-turb_kw*turb_om_kw-(turb_kw*turb_gbp_kw+turb_conn)*rate_commercial/(1-(1+rate_commercial)^-turb_life))*((1-(1+rate_commercial)^-years)/rate_commercial) | H8: Steady-state: equivalent annual cost of the turbine over 30 yr
A9: At the Green Book discount rate
A10: Turbine levelised cost of energy (LCOE) | B10: GBP/MWh | C10: =((turb_kw*turb_gbp_kw+turb_conn)*rate_public/(1-(1+rate_public)^-turb_life)+turb_kw*turb_om_kw)/turb_gen | D10: =((turb_kw*turb_gbp_kw+turb_conn)*rate_public/(1-(1+rate_public)^-turb_life)+turb_kw*turb_om_kw)/turb_gen | E10: =((turb_kw*turb_gbp_kw+turb_conn)*rate_public/(1-(1+rate_public)^-turb_life)+turb_kw*turb_om_kw)/turb_gen | F10: =((turb_kw*turb_gbp_kw+turb_conn)*rate_public/(1-(1+rate_public)^-turb_life)+turb_kw*turb_om_kw)/turb_gen | G10: =((turb_kw*turb_gbp_kw+turb_conn)*rate_public/(1-(1+rate_public)^-turb_life)+turb_kw*turb_om_kw)/turb_gen | H10: capex x CRF(rate, 20 yr) + O&M, over generation
A11: Blended electricity price to the greenhouse | B11: GBP/MWh | C11: ='Scenarios'!C29*IF('Scenarios'!C8=1,C10,pw_price)+(1-'Scenarios'!C29)*'Scenarios'!C30 | D11: ='Scenarios'!D29*IF('Scenarios'!D8=1,D10,pw_price)+(1-'Scenarios'!D29)*'Scenarios'!D30 | E11: ='Scenarios'!E29*IF('Scenarios'!E8=1,E10,pw_price)+(1-'Scenarios'!E29)*'Scenarios'!E30 | F11: ='Scenarios'!F29*IF('Scenarios'!F8=1,F10,pw_price)+(1-'Scenarios'!F29)*'Scenarios'!F30 | G11: ='Scenarios'!G29*IF('Scenarios'!G8=1,G10,pw_price)+(1-'Scenarios'!G29)*'Scenarios'!G30 | H11: Model check at 3.5 %: S0 £66.6, S3 £99.5/MWh (hourly dispatch)
A12: Turbine business NPV (sales to greenhouse at LCOE + export) | B12: GBP | C12: ='Scenarios'!C8*('Scenarios'!C28*'Scenarios'!C29*C10+MAX(turb_gen-'Scenarios'!C28*'Scenarios'!C29,0)*export_price-turb_kw*turb_om_kw-(turb_kw*turb_gbp_kw+turb_conn)*rate_public/(1-(1+rate_public)^-turb_life))*((1-(1+rate_public)^-years)/rate_public) | D12: ='Scenarios'!D8*('Scenarios'!D28*'Scenarios'!D29*D10+MAX(turb_gen-'Scenarios'!D28*'Scenarios'!D29,0)*export_price-turb_kw*turb_om_kw-(turb_kw*turb_gbp_kw+turb_conn)*rate_public/(1-(1+rate_public)^-turb_life))*((1-(1+rate_public)^-years)/rate_public) | E12: ='Scenarios'!E8*('Scenarios'!E28*'Scenarios'!E29*E10+MAX(turb_gen-'Scenarios'!E28*'Scenarios'!E29,0)*export_price-turb_kw*turb_om_kw-(turb_kw*turb_gbp_kw+turb_conn)*rate_public/(1-(1+rate_public)^-turb_life))*((1-(1+rate_public)^-years)/rate_public) | F12: ='Scenarios'!F8*('Scenarios'!F28*'Scenarios'!F29*F10+MAX(turb_gen-'Scenarios'!F28*'Scenarios'!F29,0)*export_price-turb_kw*turb_om_kw-(turb_kw*turb_gbp_kw+turb_conn)*rate_public/(1-(1+rate_public)^-turb_life))*((1-(1+rate_public)^-years)/rate_public) | G12: ='Scenarios'!G8*('Scenarios'!G28*'Scenarios'!G29*G10+MAX(turb_gen-'Scenarios'!G28*'Scenarios'!G29,0)*export_price-turb_kw*turb_om_kw-(turb_kw*turb_gbp_kw+turb_conn)*rate_public/(1-(1+rate_public)^-turb_life))*((1-(1+rate_public)^-years)/rate_public) | H12: Steady-state: equivalent annual cost of the turbine over 30 yr

Sheet Opex
A1: Annual running costs (GBP/yr) at the commercial rate
A2: Electricity at the 8 % turbine LCOE; the 3.5 % case only changes the electricity line (see Results).
A4: Item | B4: Driver | C4: S0 | D4: S1 | E4: S2 | F4: S3 | G4: S4 | H4: Note
A5: Revenue (before commission) | B5: kg x price | C5: =('Scenarios'!C33*'Scenarios'!C9)*price_cucumber | D5: =('Scenarios'!D33*'Scenarios'!D9)*price_cucumber | E5: =('Scenarios'!E33*'Scenarios'!E9)*price_cucumber | F5: =('Scenarios'!F33*'Scenarios'!F9)*price_cucumber | G5: =('Scenarios'!G33*'Scenarios'!G9)*price_cucumber | H5: Not a cost: used for commission
A6: Running costs
A7: Electricity | B7: MWh x blended price | C7: ='Scenarios'!C28*'Energy'!C7 | D7: ='Scenarios'!D28*'Energy'!D7 | E7: ='Scenarios'!E28*'Energy'!E7 | F7: ='Scenarios'!F28*'Energy'!F7 | G7: ='Scenarios'!G28*'Energy'!G7
A8: Network charge increase | B8: peak import band | C8: ='Scenarios'!C31 | D8: ='Scenarios'!D31 | E8: ='Scenarios'!E31 | F8: ='Scenarios'!F31 | G8: ='Scenarios'!G31
A9: Labour | B9: h/m² x rate x growing m² | C9: =labour_h_m2*labour_rate*'Scenarios'!C10*'Scenarios'!C9 | D9: =labour_h_m2*labour_rate*'Scenarios'!D10*'Scenarios'!D9 | E9: =labour_h_m2*labour_rate*'Scenarios'!E10*'Scenarios'!E9 | F9: =labour_h_m2*labour_rate*'Scenarios'!F10*'Scenarios'!F9 | G9: =labour_h_m2*labour_rate*'Scenarios'!G10*'Scenarios'!G9
A10: CO2 | B10: kg/m² x price x growing m² | C10: ='Scenarios'!C34*co2_price*'Scenarios'!C10*'Scenarios'!C9 | D10: ='Scenarios'!D34*co2_price*'Scenarios'!D10*'Scenarios'!D9 | E10: ='Scenarios'!E34*co2_price*'Scenarios'!E10*'Scenarios'!E9 | F10: ='Scenarios'!F34*co2_price*'Scenarios'!F10*'Scenarios'!F9 | G10: ='Scenarios'!G34*co2_price*'Scenarios'!G10*'Scenarios'!G9 | H10: Free distillery CO2 removes this
A11: Young plants | B11: per growing m² | C11: =plants_m2*'Scenarios'!C10*'Scenarios'!C9 | D11: =plants_m2*'Scenarios'!D10*'Scenarios'!D9 | E11: =plants_m2*'Scenarios'!E10*'Scenarios'!E9 | F11: =plants_m2*'Scenarios'!F10*'Scenarios'!F9 | G11: =plants_m2*'Scenarios'!G10*'Scenarios'!G9
A12: Substrate | B12: per growing m² | C12: =substrate_m2*'Scenarios'!C10*'Scenarios'!C9 | D12: =substrate_m2*'Scenarios'!D10*'Scenarios'!D9 | E12: =substrate_m2*'Scenarios'!E10*'Scenarios'!E9 | F12: =substrate_m2*'Scenarios'!F10*'Scenarios'!F9 | G12: =substrate_m2*'Scenarios'!G10*'Scenarios'!G9
A13: Fertiliser, protection, strings, water | B13: per growing m² | C13: =materials_m2*'Scenarios'!C10*'Scenarios'!C9 | D13: =materials_m2*'Scenarios'!D10*'Scenarios'!D9 | E13: =materials_m2*'Scenarios'!E10*'Scenarios'!E9 | F13: =materials_m2*'Scenarios'!F10*'Scenarios'!F9 | G13: =materials_m2*'Scenarios'!G10*'Scenarios'!G9
A14: Packing | B14: per kg | C14: =pack_gbp_kg*('Scenarios'!C33*'Scenarios'!C9) | D14: =pack_gbp_kg*('Scenarios'!D33*'Scenarios'!D9) | E14: =pack_gbp_kg*('Scenarios'!E33*'Scenarios'!E9) | F14: =pack_gbp_kg*('Scenarios'!F33*'Scenarios'!F9) | G14: =pack_gbp_kg*('Scenarios'!G33*'Scenarios'!G9)
A15: Haulage to RDCs | B15: per kg | C15: ='Scenarios'!C35*('Scenarios'!C33*'Scenarios'!C9) | D15: ='Scenarios'!D35*('Scenarios'!D33*'Scenarios'!D9) | E15: ='Scenarios'!E35*('Scenarios'!E33*'Scenarios'!E9) | F15: ='Scenarios'!F35*('Scenarios'!F33*'Scenarios'!F9) | G15: ='Scenarios'!G35*('Scenarios'!G33*'Scenarios'!G9)
A16: Structure O&M + insurance | B16: % of structure capex | C16: =om_frac*'Capex'!C13 | D16: =om_frac*'Capex'!D13 | E16: =om_frac*'Capex'!E13 | F16: =om_frac*'Capex'!F13 | G16: =om_frac*'Capex'!G13
A17: Heat pump, boiler, store O&M | B17: per MW / MWh | C17: =('Scenarios'!C22/1000*om_hp+'Scenarios'!C23/1000*om_boiler)*eur_gbp+'Scenarios'!C24/1000*om_store*1.2876*eur_gbp | D17: =('Scenarios'!D22/1000*om_hp+'Scenarios'!D23/1000*om_boiler)*eur_gbp+'Scenarios'!D24/1000*om_store*1.2876*eur_gbp | E17: =('Scenarios'!E22/1000*om_hp+'Scenarios'!E23/1000*om_boiler)*eur_gbp+'Scenarios'!E24/1000*om_store*1.2876*eur_gbp | F17: =('Scenarios'!F22/1000*om_hp+'Scenarios'!F23/1000*om_boiler)*eur_gbp+'Scenarios'!F24/1000*om_store*1.2876*eur_gbp | G17: =('Scenarios'!G22/1000*om_hp+'Scenarios'!G23/1000*om_boiler)*eur_gbp+'Scenarios'!G24/1000*om_store*1.2876*eur_gbp | H17: DEA
A18: Overheads | B18: per m² floor | C18: =overheads_m2*'Scenarios'!C9 | D18: =overheads_m2*'Scenarios'!D9 | E18: =overheads_m2*'Scenarios'!E9 | F18: =overheads_m2*'Scenarios'!F9 | G18: =overheads_m2*'Scenarios'!G9
A19: Land rent | B19: per ha incl. 30 % extra | C19: =land_rent_ha*'Scenarios'!C9/10000*(1+land_extra) | D19: =land_rent_ha*'Scenarios'!D9/10000*(1+land_extra) | E19: =land_rent_ha*'Scenarios'!E9/10000*(1+land_extra) | F19: =land_rent_ha*'Scenarios'!F9/10000*(1+land_extra) | G19: =land_rent_ha*'Scenarios'!G9/10000*(1+land_extra)
A20: Market commission | B20: % of revenue | C20: =commission*C5 | D20: =commission*D5 | E20: =commission*E5 | F20: =commission*F5 | G20: =commission*G5 | H20: 14 % (BritFarmers 2026)
A21: TOTAL RUNNING COSTS | C21: =C7+C8+C9+C10+C11+C12+C13+C14+C15+C16+C17+C18+C19+C20 | D21: =D7+D8+D9+D10+D11+D12+D13+D14+D15+D16+D17+D18+D19+D20 | E21: =E7+E8+E9+E10+E11+E12+E13+E14+E15+E16+E17+E18+E19+E20 | F21: =F7+F8+F9+F10+F11+F12+F13+F14+F15+F16+F17+F18+F19+F20 | G21: =G7+G8+G9+G10+G11+G12+G13+G14+G15+G16+G17+G18+G19+G20
A22: Running cost per kg | C22: =C21/('Scenarios'!C33*'Scenarios'!C9) | D22: =D21/('Scenarios'!D33*'Scenarios'!D9) | E22: =E21/('Scenarios'!E33*'Scenarios'!E9) | F22: =F21/('Scenarios'!F33*'Scenarios'!F9) | G22: =G21/('Scenarios'!G33*'Scenarios'!G9)

Sheet Results
A1: Results: initial spend, cost per kg, margin and NPV
A2: Equivalent annual capital cost = capex x CRF(rate, item life); covers replacements of shorter-lived items.
A4: Result | B4: Unit | C4: S0 | D4: S1 | E4: S2 | F4: S3 | G4: S4 | H4: Note
A5: Initial expenditure
A6: Greenhouse | B6: GBP | C6: ='Capex'!C24 | D6: ='Capex'!D24 | E6: ='Capex'!E24 | F6: ='Capex'!F24 | G6: ='Capex'!G24
A7: Energy route (turbine) | B7: GBP | C7: ='Capex'!C28 | D7: ='Capex'!D28 | E7: ='Capex'!E28 | F7: ='Capex'!F28 | G7: ='Capex'!G28
A8: Total day-one spend | B8: GBP | C8: ='Capex'!C29 | D8: ='Capex'!D29 | E8: ='Capex'!E29 | F8: ='Capex'!F29 | G8: ='Capex'!G29
A9: Reduction in day-one spend vs S0 | B9: % | C9: =1-C8/$C$8 | D9: =1-D8/$C$8 | E9: =1-E8/$C$8 | F9: =1-F8/$C$8 | G9: =1-G8/$C$8
A10: At the commercial discount rate
A11: Equivalent annual capital cost (greenhouse) | B11: GBP/yr | C11: ='Capex'!C6*rate_commercial/(1-(1+rate_commercial)^-life_steel)+'Capex'!C7*rate_commercial/(1-(1+rate_commercial)^-life_aluminium)+'Capex'!C8*rate_commercial/(1-(1+rate_commercial)^-life_glass_dbl_ar_m2)+'Capex'!C9*rate_commercial/(1-(1+rate_commercial)^-life_concrete)+'Capex'!C10*rate_commercial/(1-(1+rate_commercial)^-life_heating_pipe_m)+'Capex'!C11*rate_commercial/(1-(1+rate_commercial)^-life_energy_screen_m2)+'Capex'!C12*rate_commercial/(1-(1+rate_commercial)^-life_resid)+'Capex'!C15*rate_commercial/(1-(1+rate_commercial)^-life_hp)+'Capex'!C16*rate_commercial/(1-(1+rate_commercial)^-life_boiler)+'Capex'!C17*rate_commercial/(1-(1+rate_commercial)^-life_store)+'Capex'!C20*rate_commercial/(1-(1+rate_commercial)^-years)+'Capex'!C22*rate_commercial/(1-(1+rate_commercial)^-years)+'Capex'!C23*rate_commercial/(1-(1+rate_commercial)^-years) | D11: ='Capex'!D6*rate_commercial/(1-(1+rate_commercial)^-life_steel)+'Capex'!D7*rate_commercial/(1-(1+rate_commercial)^-life_aluminium)+'Capex'!D8*rate_commercial/(1-(1+rate_commercial)^-life_glass_dbl_ar_m2)+'Capex'!D9*rate_commercial/(1-(1+rate_commercial)^-life_concrete)+'Capex'!D10*rate_commercial/(1-(1+rate_commercial)^-life_heating_pipe_m)+'Capex'!D11*rate_commercial/(1-(1+rate_commercial)^-life_energy_screen_m2)+'Capex'!D12*rate_commercial/(1-(1+rate_commercial)^-life_resid)+'Capex'!D15*rate_commercial/(1-(1+rate_commercial)^-life_hp)+'Capex'!D16*rate_commercial/(1-(1+rate_commercial)^-life_boiler)+'Capex'!D17*rate_commercial/(1-(1+rate_commercial)^-life_store)+'Capex'!D20*rate_commercial/(1-(1+rate_commercial)^-years)+'Capex'!D22*rate_commercial/(1-(1+rate_commercial)^-years)+'Capex'!D23*rate_commercial/(1-(1+rate_commercial)^-years) | E11: ='Capex'!E6*rate_commercial/(1-(1+rate_commercial)^-life_steel)+'Capex'!E7*rate_commercial/(1-(1+rate_commercial)^-life_aluminium)+'Capex'!E8*rate_commercial/(1-(1+rate_commercial)^-life_glass_dbl_ar_m2)+'Capex'!E9*rate_commercial/(1-(1+rate_commercial)^-life_concrete)+'Capex'!E10*rate_commercial/(1-(1+rate_commercial)^-life_heating_pipe_m)+'Capex'!E11*rate_commercial/(1-(1+rate_commercial)^-life_energy_screen_m2)+'Capex'!E12*rate_commercial/(1-(1+rate_commercial)^-life_resid)+'Capex'!E15*rate_commercial/(1-(1+rate_commercial)^-life_hp)+'Capex'!E16*rate_commercial/(1-(1+rate_commercial)^-life_boiler)+'Capex'!E17*rate_commercial/(1-(1+rate_commercial)^-life_store)+'Capex'!E20*rate_commercial/(1-(1+rate_commercial)^-years)+'Capex'!E22*rate_commercial/(1-(1+rate_commercial)^-years)+'Capex'!E23*rate_commercial/(1-(1+rate_commercial)^-years) | F11: ='Capex'!F6*rate_commercial/(1-(1+rate_commercial)^-life_steel)+'Capex'!F7*rate_commercial/(1-(1+rate_commercial)^-life_aluminium)+'Capex'!F8*rate_commercial/(1-(1+rate_commercial)^-life_glass_dbl_ar_m2)+'Capex'!F9*rate_commercial/(1-(1+rate_commercial)^-life_concrete)+'Capex'!F10*rate_commercial/(1-(1+rate_commercial)^-life_heating_pipe_m)+'Capex'!F11*rate_commercial/(1-(1+rate_commercial)^-life_energy_screen_m2)+'Capex'!F12*rate_commercial/(1-(1+rate_commercial)^-life_resid)+'Capex'!F15*rate_commercial/(1-(1+rate_commercial)^-life_hp)+'Capex'!F16*rate_commercial/(1-(1+rate_commercial)^-life_boiler)+'Capex'!F17*rate_commercial/(1-(1+rate_commercial)^-life_store)+'Capex'!F20*rate_commercial/(1-(1+rate_commercial)^-years)+'Capex'!F22*rate_commercial/(1-(1+rate_commercial)^-years)+'Capex'!F23*rate_commercial/(1-(1+rate_commercial)^-years) | G11: ='Capex'!G6*rate_commercial/(1-(1+rate_commercial)^-life_steel)+'Capex'!G7*rate_commercial/(1-(1+rate_commercial)^-life_aluminium)+'Capex'!G8*rate_commercial/(1-(1+rate_commercial)^-life_glass_dbl_ar_m2)+'Capex'!G9*rate_commercial/(1-(1+rate_commercial)^-life_concrete)+'Capex'!G10*rate_commercial/(1-(1+rate_commercial)^-life_heating_pipe_m)+'Capex'!G11*rate_commercial/(1-(1+rate_commercial)^-life_energy_screen_m2)+'Capex'!G12*rate_commercial/(1-(1+rate_commercial)^-life_resid)+'Capex'!G15*rate_commercial/(1-(1+rate_commercial)^-life_hp)+'Capex'!G16*rate_commercial/(1-(1+rate_commercial)^-life_boiler)+'Capex'!G17*rate_commercial/(1-(1+rate_commercial)^-life_store)+'Capex'!G20*rate_commercial/(1-(1+rate_commercial)^-years)+'Capex'!G22*rate_commercial/(1-(1+rate_commercial)^-years)+'Capex'!G23*rate_commercial/(1-(1+rate_commercial)^-years)
A12: Running costs (electricity at this rate's turbine LCOE) | B12: GBP/yr | C12: ='Opex'!C21-'Opex'!C7+'Scenarios'!C28*'Energy'!C7 | D12: ='Opex'!D21-'Opex'!D7+'Scenarios'!D28*'Energy'!D7 | E12: ='Opex'!E21-'Opex'!E7+'Scenarios'!E28*'Energy'!E7 | F12: ='Opex'!F21-'Opex'!F7+'Scenarios'!F28*'Energy'!F7 | G12: ='Opex'!G21-'Opex'!G7+'Scenarios'!G28*'Energy'!G7
A13: Production | B13: kg/yr | C13: ='Scenarios'!C33*'Scenarios'!C9 | D13: ='Scenarios'!D33*'Scenarios'!D9 | E13: ='Scenarios'!E33*'Scenarios'!E9 | F13: ='Scenarios'!F33*'Scenarios'!F9 | G13: ='Scenarios'!G33*'Scenarios'!G9
A14: LEVELISED COST OF PRODUCTION | B14: GBP/kg | C14: =(C11+C12)/C13 | D14: =(D11+D12)/D13 | E14: =(E11+E12)/E13 | F14: =(F11+F12)/F13 | G14: =(G11+G12)/G13
A15: of which capital | B15: GBP/kg | C15: =C11/C13 | D15: =D11/D13 | E15: =E11/E13 | F15: =F11/F13 | G15: =G11/G13
A16: Price received (DEFRA wholesale, harvest-weighted) | B16: GBP/kg | C16: =price_cucumber | D16: =price_cucumber | E16: =price_cucumber | F16: =price_cucumber | G16: =price_cucumber
A17: Margin per kg (price - cost) | B17: GBP/kg | C17: =price_cucumber-C14 | D17: =price_cucumber-D14 | E17: =price_cucumber-E14 | F17: =price_cucumber-F14 | G17: =price_cucumber-G14
A18: Break-even price (covers commission) | B18: GBP/kg | C18: =(C11+C12-'Opex'!C20)/(C13*(1-commission)) | D18: =(D11+D12-'Opex'!D20)/(D13*(1-commission)) | E18: =(E11+E12-'Opex'!E20)/(E13*(1-commission)) | F18: =(F11+F12-'Opex'!F20)/(F13*(1-commission)) | G18: =(G11+G12-'Opex'!G20)/(G13*(1-commission))
A19: Greenhouse NPV (steady-state, 30 yr) | B19: GBP | C19: =(C13*price_cucumber-C12-C11)*((1-(1+rate_commercial)^-years)/rate_commercial) | D19: =(D13*price_cucumber-D12-D11)*((1-(1+rate_commercial)^-years)/rate_commercial) | E19: =(E13*price_cucumber-E12-E11)*((1-(1+rate_commercial)^-years)/rate_commercial) | F19: =(F13*price_cucumber-F12-F11)*((1-(1+rate_commercial)^-years)/rate_commercial) | G19: =(G13*price_cucumber-G12-G11)*((1-(1+rate_commercial)^-years)/rate_commercial)
A20: Turbine business NPV (link to Energy) | B20: GBP | C20: ='Energy'!C8 | D20: ='Energy'!D8 | E20: ='Energy'!E8 | F20: ='Energy'!F8 | G20: ='Energy'!G8
A21: At the Green Book discount rate
A22: Equivalent annual capital cost (greenhouse) | B22: GBP/yr | C22: ='Capex'!C6*rate_public/(1-(1+rate_public)^-life_steel)+'Capex'!C7*rate_public/(1-(1+rate_public)^-life_aluminium)+'Capex'!C8*rate_public/(1-(1+rate_public)^-life_glass_dbl_ar_m2)+'Capex'!C9*rate_public/(1-(1+rate_public)^-life_concrete)+'Capex'!C10*rate_public/(1-(1+rate_public)^-life_heating_pipe_m)+'Capex'!C11*rate_public/(1-(1+rate_public)^-life_energy_screen_m2)+'Capex'!C12*rate_public/(1-(1+rate_public)^-life_resid)+'Capex'!C15*rate_public/(1-(1+rate_public)^-life_hp)+'Capex'!C16*rate_public/(1-(1+rate_public)^-life_boiler)+'Capex'!C17*rate_public/(1-(1+rate_public)^-life_store)+'Capex'!C20*rate_public/(1-(1+rate_public)^-years)+'Capex'!C22*rate_public/(1-(1+rate_public)^-years)+'Capex'!C23*rate_public/(1-(1+rate_public)^-years) | D22: ='Capex'!D6*rate_public/(1-(1+rate_public)^-life_steel)+'Capex'!D7*rate_public/(1-(1+rate_public)^-life_aluminium)+'Capex'!D8*rate_public/(1-(1+rate_public)^-life_glass_dbl_ar_m2)+'Capex'!D9*rate_public/(1-(1+rate_public)^-life_concrete)+'Capex'!D10*rate_public/(1-(1+rate_public)^-life_heating_pipe_m)+'Capex'!D11*rate_public/(1-(1+rate_public)^-life_energy_screen_m2)+'Capex'!D12*rate_public/(1-(1+rate_public)^-life_resid)+'Capex'!D15*rate_public/(1-(1+rate_public)^-life_hp)+'Capex'!D16*rate_public/(1-(1+rate_public)^-life_boiler)+'Capex'!D17*rate_public/(1-(1+rate_public)^-life_store)+'Capex'!D20*rate_public/(1-(1+rate_public)^-years)+'Capex'!D22*rate_public/(1-(1+rate_public)^-years)+'Capex'!D23*rate_public/(1-(1+rate_public)^-years) | E22: ='Capex'!E6*rate_public/(1-(1+rate_public)^-life_steel)+'Capex'!E7*rate_public/(1-(1+rate_public)^-life_aluminium)+'Capex'!E8*rate_public/(1-(1+rate_public)^-life_glass_dbl_ar_m2)+'Capex'!E9*rate_public/(1-(1+rate_public)^-life_concrete)+'Capex'!E10*rate_public/(1-(1+rate_public)^-life_heating_pipe_m)+'Capex'!E11*rate_public/(1-(1+rate_public)^-life_energy_screen_m2)+'Capex'!E12*rate_public/(1-(1+rate_public)^-life_resid)+'Capex'!E15*rate_public/(1-(1+rate_public)^-life_hp)+'Capex'!E16*rate_public/(1-(1+rate_public)^-life_boiler)+'Capex'!E17*rate_public/(1-(1+rate_public)^-life_store)+'Capex'!E20*rate_public/(1-(1+rate_public)^-years)+'Capex'!E22*rate_public/(1-(1+rate_public)^-years)+'Capex'!E23*rate_public/(1-(1+rate_public)^-years) | F22: ='Capex'!F6*rate_public/(1-(1+rate_public)^-life_steel)+'Capex'!F7*rate_public/(1-(1+rate_public)^-life_aluminium)+'Capex'!F8*rate_public/(1-(1+rate_public)^-life_glass_dbl_ar_m2)+'Capex'!F9*rate_public/(1-(1+rate_public)^-life_concrete)+'Capex'!F10*rate_public/(1-(1+rate_public)^-life_heating_pipe_m)+'Capex'!F11*rate_public/(1-(1+rate_public)^-life_energy_screen_m2)+'Capex'!F12*rate_public/(1-(1+rate_public)^-life_resid)+'Capex'!F15*rate_public/(1-(1+rate_public)^-life_hp)+'Capex'!F16*rate_public/(1-(1+rate_public)^-life_boiler)+'Capex'!F17*rate_public/(1-(1+rate_public)^-life_store)+'Capex'!F20*rate_public/(1-(1+rate_public)^-years)+'Capex'!F22*rate_public/(1-(1+rate_public)^-years)+'Capex'!F23*rate_public/(1-(1+rate_public)^-years) | G22: ='Capex'!G6*rate_public/(1-(1+rate_public)^-life_steel)+'Capex'!G7*rate_public/(1-(1+rate_public)^-life_aluminium)+'Capex'!G8*rate_public/(1-(1+rate_public)^-life_glass_dbl_ar_m2)+'Capex'!G9*rate_public/(1-(1+rate_public)^-life_concrete)+'Capex'!G10*rate_public/(1-(1+rate_public)^-life_heating_pipe_m)+'Capex'!G11*rate_public/(1-(1+rate_public)^-life_energy_screen_m2)+'Capex'!G12*rate_public/(1-(1+rate_public)^-life_resid)+'Capex'!G15*rate_public/(1-(1+rate_public)^-life_hp)+'Capex'!G16*rate_public/(1-(1+rate_public)^-life_boiler)+'Capex'!G17*rate_public/(1-(1+rate_public)^-life_store)+'Capex'!G20*rate_public/(1-(1+rate_public)^-years)+'Capex'!G22*rate_public/(1-(1+rate_public)^-years)+'Capex'!G23*rate_public/(1-(1+rate_public)^-years)
A23: Running costs (electricity at this rate's turbine LCOE) | B23: GBP/yr | C23: ='Opex'!C21-'Opex'!C7+'Scenarios'!C28*'Energy'!C11 | D23: ='Opex'!D21-'Opex'!D7+'Scenarios'!D28*'Energy'!D11 | E23: ='Opex'!E21-'Opex'!E7+'Scenarios'!E28*'Energy'!E11 | F23: ='Opex'!F21-'Opex'!F7+'Scenarios'!F28*'Energy'!F11 | G23: ='Opex'!G21-'Opex'!G7+'Scenarios'!G28*'Energy'!G11
A24: Production | B24: kg/yr | C24: ='Scenarios'!C33*'Scenarios'!C9 | D24: ='Scenarios'!D33*'Scenarios'!D9 | E24: ='Scenarios'!E33*'Scenarios'!E9 | F24: ='Scenarios'!F33*'Scenarios'!F9 | G24: ='Scenarios'!G33*'Scenarios'!G9
A25: LEVELISED COST OF PRODUCTION | B25: GBP/kg | C25: =(C22+C23)/C24 | D25: =(D22+D23)/D24 | E25: =(E22+E23)/E24 | F25: =(F22+F23)/F24 | G25: =(G22+G23)/G24
A26: of which capital | B26: GBP/kg | C26: =C22/C24 | D26: =D22/D24 | E26: =E22/E24 | F26: =F22/F24 | G26: =G22/G24
A27: Price received (DEFRA wholesale, harvest-weighted) | B27: GBP/kg | C27: =price_cucumber | D27: =price_cucumber | E27: =price_cucumber | F27: =price_cucumber | G27: =price_cucumber
A28: Margin per kg (price - cost) | B28: GBP/kg | C28: =price_cucumber-C25 | D28: =price_cucumber-D25 | E28: =price_cucumber-E25 | F28: =price_cucumber-F25 | G28: =price_cucumber-G25
A29: Break-even price (covers commission) | B29: GBP/kg | C29: =(C22+C23-'Opex'!C20)/(C24*(1-commission)) | D29: =(D22+D23-'Opex'!D20)/(D24*(1-commission)) | E29: =(E22+E23-'Opex'!E20)/(E24*(1-commission)) | F29: =(F22+F23-'Opex'!F20)/(F24*(1-commission)) | G29: =(G22+G23-'Opex'!G20)/(G24*(1-commission))
A30: Greenhouse NPV (steady-state, 30 yr) | B30: GBP | C30: =(C24*price_cucumber-C23-C22)*((1-(1+rate_public)^-years)/rate_public) | D30: =(D24*price_cucumber-D23-D22)*((1-(1+rate_public)^-years)/rate_public) | E30: =(E24*price_cucumber-E23-E22)*((1-(1+rate_public)^-years)/rate_public) | F30: =(F24*price_cucumber-F23-F22)*((1-(1+rate_public)^-years)/rate_public) | G30: =(G24*price_cucumber-G23-G22)*((1-(1+rate_public)^-years)/rate_public)
A31: Turbine business NPV (link to Energy) | B31: GBP | C31: ='Energy'!C12 | D31: ='Energy'!D12 | E31: ='Energy'!E12 | F31: ='Energy'!F12 | G31: ='Energy'!G12
A33: Check against the full cash-flow model (cashflow.py, S0, 5 % commission, with ramp-up and residual value)
A34: Levelised cost at 8 % (cashflow.py) | B34: GBP/kg | C34: 1.585 | H34: This sheet uses 14 % commission and the 8 %-rate turbine LCOE; set Inputs commission to 5 % to compare like for like (expect within a few pence: no ramp-up year, no residual value here)
A35: Levelised cost at 3.5 % (cashflow.py) | B35: GBP/kg | C35: 1.32 | H35: This sheet uses 14 % commission and the 8 %-rate turbine LCOE; set Inputs commission to 5 % to compare like for like (expect within a few pence: no ramp-up year, no residual value here)
A36: Greenhouse capex, S0 (cashflow.py) | B36: GBP | C36: 4073887

Sheet Scale
A1: Scale explorer: how cost per m² changes with size
A2: Today's model scales everything per m² except the HV connection. Here each cost has its own driver; fixed and perimeter shares come from residual_items.csv and the geometry (BP19b/d); quotes will replace them.
A4: Fixed share of the residual (climate computer core, design, plant room, water basin) | B4: 0.177
A5: Perimeter items: share of structure that is walls / edge foundations | B5: 0.101
A6: Heat pump design load per m² (from S0) | B6: ='Scenarios'!C21/'Scenarios'!C9*1000 | C6: W/m²
A7: Heat pump share of design load (S0 rule) | B7: ='Scenarios'!C22/'Scenarios'!C21
A9: Item (GBP per m²) | B9: 1 ha | C9: 2 ha | D9: 5 ha | E9: 10 ha | F9: 20 ha | G9: 30 ha | I9: Driver
A10: Area (m²) | B10: 10000 | C10: 20000 | D10: 50000 | E10: 100000 | F10: 200000 | G10: 300000
A11: Structure, area items | B11: =('Capex'!$C$13-'Capex'!$C$12)/'Scenarios'!C9*(1-perim_share) | C11: =('Capex'!$C$13-'Capex'!$C$12)/'Scenarios'!C9*(1-perim_share) | D11: =('Capex'!$C$13-'Capex'!$C$12)/'Scenarios'!C9*(1-perim_share) | E11: =('Capex'!$C$13-'Capex'!$C$12)/'Scenarios'!C9*(1-perim_share) | F11: =('Capex'!$C$13-'Capex'!$C$12)/'Scenarios'!C9*(1-perim_share) | G11: =('Capex'!$C$13-'Capex'!$C$12)/'Scenarios'!C9*(1-perim_share) | I11: per m² (flat rate; volume discounts need quotes)
A12: Structure, perimeter items | B12: =('Capex'!$C$13-'Capex'!$C$12)/'Scenarios'!C9*perim_share*SQRT('Scenarios'!C9/B10) | C12: =('Capex'!$C$13-'Capex'!$C$12)/'Scenarios'!C9*perim_share*SQRT('Scenarios'!C9/C10) | D12: =('Capex'!$C$13-'Capex'!$C$12)/'Scenarios'!C9*perim_share*SQRT('Scenarios'!C9/D10) | E12: =('Capex'!$C$13-'Capex'!$C$12)/'Scenarios'!C9*perim_share*SQRT('Scenarios'!C9/E10) | F12: =('Capex'!$C$13-'Capex'!$C$12)/'Scenarios'!C9*perim_share*SQRT('Scenarios'!C9/F10) | G12: =('Capex'!$C$13-'Capex'!$C$12)/'Scenarios'!C9*perim_share*SQRT('Scenarios'!C9/G10) | I12: per m of perimeter: falls as 1/sqrt(area)
A13: Residual, variable part | B13: =r_resid*(1-fixed_resid_share) | C13: =r_resid*(1-fixed_resid_share) | D13: =r_resid*(1-fixed_resid_share) | E13: =r_resid*(1-fixed_resid_share) | F13: =r_resid*(1-fixed_resid_share) | G13: =r_resid*(1-fixed_resid_share) | I13: per m²
A14: Residual, fixed part | B14: =r_resid*fixed_resid_share*'Scenarios'!C9/B10 | C14: =r_resid*fixed_resid_share*'Scenarios'!C9/C10 | D14: =r_resid*fixed_resid_share*'Scenarios'!C9/D10 | E14: =r_resid*fixed_resid_share*'Scenarios'!C9/E10 | F14: =r_resid*fixed_resid_share*'Scenarios'!C9/F10 | G14: =r_resid*fixed_resid_share*'Scenarios'!C9/G10 | I14: fixed per site: falls as 1/area
A15: Heat pump (DEA curve) | B15: =hp_load_w_per_m2/1000*hp_share*IF(hp_load_w_per_m2*hp_share*B10/1000000<=1,dea_hp_1,IF(hp_load_w_per_m2*hp_share*B10/1000000<=3,dea_hp_1+LN(hp_load_w_per_m2*hp_share*B10/1000000)/LN(3)*(dea_hp_3-dea_hp_1),IF(hp_load_w_per_m2*hp_share*B10/1000000<=10,dea_hp_3+LN(hp_load_w_per_m2*hp_share*B10/1000000/3)/LN(10/3)*(dea_hp_10-dea_hp_3),dea_hp_10)))*1000*eur_gbp | C15: =hp_load_w_per_m2/1000*hp_share*IF(hp_load_w_per_m2*hp_share*C10/1000000<=1,dea_hp_1,IF(hp_load_w_per_m2*hp_share*C10/1000000<=3,dea_hp_1+LN(hp_load_w_per_m2*hp_share*C10/1000000)/LN(3)*(dea_hp_3-dea_hp_1),IF(hp_load_w_per_m2*hp_share*C10/1000000<=10,dea_hp_3+LN(hp_load_w_per_m2*hp_share*C10/1000000/3)/LN(10/3)*(dea_hp_10-dea_hp_3),dea_hp_10)))*1000*eur_gbp | D15: =hp_load_w_per_m2/1000*hp_share*IF(hp_load_w_per_m2*hp_share*D10/1000000<=1,dea_hp_1,IF(hp_load_w_per_m2*hp_share*D10/1000000<=3,dea_hp_1+LN(hp_load_w_per_m2*hp_share*D10/1000000)/LN(3)*(dea_hp_3-dea_hp_1),IF(hp_load_w_per_m2*hp_share*D10/1000000<=10,dea_hp_3+LN(hp_load_w_per_m2*hp_share*D10/1000000/3)/LN(10/3)*(dea_hp_10-dea_hp_3),dea_hp_10)))*1000*eur_gbp | E15: =hp_load_w_per_m2/1000*hp_share*IF(hp_load_w_per_m2*hp_share*E10/1000000<=1,dea_hp_1,IF(hp_load_w_per_m2*hp_share*E10/1000000<=3,dea_hp_1+LN(hp_load_w_per_m2*hp_share*E10/1000000)/LN(3)*(dea_hp_3-dea_hp_1),IF(hp_load_w_per_m2*hp_share*E10/1000000<=10,dea_hp_3+LN(hp_load_w_per_m2*hp_share*E10/1000000/3)/LN(10/3)*(dea_hp_10-dea_hp_3),dea_hp_10)))*1000*eur_gbp | F15: =hp_load_w_per_m2/1000*hp_share*IF(hp_load_w_per_m2*hp_share*F10/1000000<=1,dea_hp_1,IF(hp_load_w_per_m2*hp_share*F10/1000000<=3,dea_hp_1+LN(hp_load_w_per_m2*hp_share*F10/1000000)/LN(3)*(dea_hp_3-dea_hp_1),IF(hp_load_w_per_m2*hp_share*F10/1000000<=10,dea_hp_3+LN(hp_load_w_per_m2*hp_share*F10/1000000/3)/LN(10/3)*(dea_hp_10-dea_hp_3),dea_hp_10)))*1000*eur_gbp | G15: =hp_load_w_per_m2/1000*hp_share*IF(hp_load_w_per_m2*hp_share*G10/1000000<=1,dea_hp_1,IF(hp_load_w_per_m2*hp_share*G10/1000000<=3,dea_hp_1+LN(hp_load_w_per_m2*hp_share*G10/1000000)/LN(3)*(dea_hp_3-dea_hp_1),IF(hp_load_w_per_m2*hp_share*G10/1000000<=10,dea_hp_3+LN(hp_load_w_per_m2*hp_share*G10/1000000/3)/LN(10/3)*(dea_hp_10-dea_hp_3),dea_hp_10)))*1000*eur_gbp | I15: per kW, cheaper per kW above 1 MW
A16: Hot-water store | B16: ='Capex'!$C$17/'Scenarios'!C9 | C16: ='Capex'!$C$17/'Scenarios'!C9 | D16: ='Capex'!$C$17/'Scenarios'!C9 | E16: ='Capex'!$C$17/'Scenarios'!C9 | F16: ='Capex'!$C$17/'Scenarios'!C9 | G16: ='Capex'!$C$17/'Scenarios'!C9 | I16: per kWh (flat here; DEA tanks get cheaper with size)
A17: HV import connection | B17: =hv_conn/B10 | C17: =hv_conn/C10 | D17: =hv_conn/D10 | E17: =hv_conn/E10 | F17: =hv_conn/F10 | G17: =hv_conn/G10 | I17: fixed per site (BP16: should step with kVA)
A18: Subtotal | B18: =SUM(B11:B17) | C18: =SUM(C11:C17) | D18: =SUM(D11:D17) | E18: =SUM(E11:E17) | F18: =SUM(F11:F17) | G18: =SUM(G11:G17)
A19: Greenhouse capex per m² incl. development + contingency | B19: =B18*(1+dev_frac+contingency) | C19: =C18*(1+dev_frac+contingency) | D19: =D18*(1+dev_frac+contingency) | E19: =E18*(1+dev_frac+contingency) | F19: =F18*(1+dev_frac+contingency) | G19: =G18*(1+dev_frac+contingency)
A20: Change vs 1 ha | B20: =B19/$B$19-1 | C20: =C19/$B$19-1 | D20: =D19/$B$19-1 | E20: =E19/$B$19-1 | F20: =F19/$B$19-1 | G20: =G19/$B$19-1
A22: Read: at 0 % fixed residual and 0 % perimeter share this reproduces today's model, where only the HV connection and the heat pump curve give any economy of scale, which is why the size study found bigger houses no cheaper.
A23: Evidence so far: Dutch growers consolidate onto 50-500 ha businesses for economies of scale (RaboResearch 2025, p. 6), but no free source quantifies capex vs size. KWIN-AGV gives model-nursery investments by size (paywalled).
A24: Labour stays per m² (RaboResearch 2025 fig. 6: Dutch m² per annual work unit stable 2000-2023).

Sheet Capex Levers
A1: Capex-reduction levers
A2: Modelled values link to Results. 'To test' rows are the work plan (HANDOFF BP13-BP19).
A4: Lever | B4: Status | C4: Change in day-one spend | D4: Change in £/kg at 8 % | E4: Evidence | F4: Next step / caveat
A5: LP-sized heat pump + electric peak boiler + store (double glass) | B5: modelled | C5: ='Results'!D8-'Results'!C8 | D5: ='Results'!D14-'Results'!C14 | E5: DEA ch. 40/41; Stanghellini §8.9 | F5: Boiler also replaces the full-standby heat pump as cold-year / outage backup
A6: Single glass + LP-sized heat pump + boiler + store | B6: modelled | C6: ='Results'!E8-'Results'!C8 | D6: ='Results'!E14-'Results'!C14 | E6: Model: yield +14 %, heat +74 % | F6: Rests on the crop model's light response; check with GreenLight / grower data
A7: Private-wire PPA instead of owning the turbine | B7: modelled | C7: ='Results'!F8-'Results'!E8 | D7: ='Results'!F14-'Results'!E14 | E7: Savills 2025 PPA £80-120/MWh | F7: Needs an adjacent wind farm: Girvan (16 large turbines within 3.1 km), not Stranraer
A8: Supplier quotes for placeholder items (glass, aluminium, pipe, screen) | B8: to test | E8: Placeholders ~46 % of structure | F8: Issue RFQ_SPEC.md; try quotes in 'Rates' (low column)
A9: Itemise the £94/m² residual (climate computer, irrigation, install) | B9: itemised, unquoted | E9: data/residual_items.csv; climate computer from a Dutch installer price page (2026); the rest placeholder | F9: RFQ_SPEC §3.7 issued as a draft; 85 % of the residual is still a placeholder split, fixed share 17.7 %
