Workbook

Sheet Results
A1: Lead finance model: results
A2: Supplier credit (ECA) + plant asset finance, 1-yr holiday, DSRA (finance.py central scheme). Change blue cells on Inputs.
A4: Output | B4: Workbook | C4: finance.py (default inputs)
A5: Capex (GBP) | B5: =SUM(Inputs!$C$36:$C$52)*Inputs!$C$11 -> 11453365 | C5: 11453365
A6: Debt drawn (GBP) | B6: =Cashflow!C20+Cashflow!C23 -> 8116837.3 | C6: 8116837.3
A7: Equity at close (GBP) | B7: =-Cashflow!C38 -> 4343008.2 | C7: 4343008.2
A8: Project IRR, real pre-tax | B8: =IRR(Cashflow!C10:AG10) -> 0.15215104 | C8: 0.15215104
A9: Equity IRR, nominal post-tax | B9: =IRR(Cashflow!C38:AG38) -> 0.2183479 | C9: 0.2183479
A10: Equity IRR, real | B10: =(1+B9)/(1+Inputs!$C$6)-1 -> 0.19445873 | C10: 0.19445873
A11: DSCR year 1 | B11: =Cashflow!D35 -> 2.1251214 | C11: 2.1251214
A12: Minimum DSCR | B12: =MIN(Cashflow!D35:AG35) -> 1.5625679 | C12: 1.5625679
A13: Tax paid over 30 yr (GBP) | B13: =SUM(Cashflow!C30:AG30) -> 15254225 | C13: 15254225
A14: Equity NPV at the hurdle (GBP) | B14: =NPV(Inputs!$C$28,Cashflow!D38:AG38)+Cashflow!C38 -> 4567050.8 | C14: 4567050.8
A15: Lender test met (min DSCR >= target) | B15: =IF(B12>=Inputs!$C$27,"yes","NO") -> yes
A17: Minimum real price for DSCR 1.25 (finance.py solver): flex Inputs!price until 'Lender test met' turns yes.
A18: Minimum price (GBP/kg) | C18: 1.2369678

Sheet Inputs
A1: Lead finance model: inputs (blue = input)
A2: Lit lead 2.9 ha, 150 umol, 2 PPA turbines, Stranraer; physics from lit_open.json; terms and tiers in finance.py
A4: Contract price, real (year-0 GBP/kg) | C4: 1.3994474 | D4: default = import parity 1.555 x 0.90; CPI-indexed
A5: Import parity (GBP/kg) | C5: 1.5549416 | D5: monthly CIF + GBP 0.162 haul, weighted by own harvest
A6: CPI | C6: 0.02 | D6: Bank of England target
A7: Corporation tax | C7: 0.25 | D7: main rate
A8: Output at full yield (kg/yr) | C8: 2698092.5 | D8: model, before stresses
A9: Year-1 output share | C9: 0.8 | D9: first-crop establishment
A10: Stress: yield x | C10: 1
A11: Stress: capex x (incl. replacements) | C11: 1
A12: Stress: power cost x | C12: 1
A13: CO2 price (GBP/kg) | C13: 0.06 | D13: by-product CO2 (PLACEHOLDER); model base 0.06
A14: Stress: labour x | C14: 1
A15: Share of labour that scales with kg | C15: 0.5 | D15: PLACEHOLDER
A16: ECA supplier credit: advance on structure | C16: 0.85 | D16: OECD Arrangement max 85 %
A17: ECA supplier credit: fixed rate | C17: 0.0581 | D17: OECD GBP CIRR, 8-yr bucket, 15 Sep-14 Oct 2026
A18: ECA supplier credit: tenor (yr) | C18: 15 | D18: max 15
A19: ECA supplier credit: interest-only years | C19: 1 | D19: needs the ECA's agreement
A20: ECA premium, up front | C20: 0.02 | D20: PLACEHOLDER
A21: Plant asset finance: advance | C21: 0.9 | D21: PLACEHOLDER
A22: Plant asset finance: rate | C22: 0.07 | D22: Bank Rate 3.75 % + 3.25 %, PLACEHOLDER
A23: Plant asset finance: tenor (yr) | C23: 10
A24: Plant asset finance: interest-only years | C24: 1
A25: Plant asset finance: arrangement fee | C25: 0.01 | D25: PLACEHOLDER
A26: Capital grant (GBP) | C26: 0 | D26: FDPSS up to GBP 0.4 M, packhouse only (GRANTS.md)
A27: Lender minimum DSCR | C27: 1.25 | D27: PLACEHOLDER 1.20-1.35
A28: Equity hurdle, nominal post-tax | C28: 0.12 | D28: PLACEHOLDER
A29: Working capital (months of opex) | C29: 2
A30: DSRA (months of next year's debt service) | C30: 6
A31: Maintenance-reserve rate (real) | C31: 0.06 | D31: levels the lumpy replacements for CFADS
A32: Special-rate first-year allowance | C32: 0.5 | D32: CAA 2001 s.45S
A33: Special-rate writing-down allowance | C33: 0.06
A35: Capex lines (GBP, year 0) | C35: GBP | D35: Finance / allowance class
A36: steel | B36: ECA | C36: 794190.25 | D36: main
A37: aluminium | B37: ECA | C37: 191960.28 | D37: main
A38: glass_single_m2 | B38: ECA | C38: 833160.95 | D38: main
A39: concrete | B39: ECA | C39: 65768.223 | D39: main
A40: pir_panel_m2 | B40: ECA | C40: 0 | D40: main
A41: heating_pipe_m | B41: ECA | C41: 1044000 | D41: special
A42: energy_screen_m2 | B42: ECA | C42: 174000 | D42: main
...

Sheet Cashflow
A1: Lead finance model: annual cash flow (nominal GBP unless marked real)
C3: 0 | D3: 1 | E3: 2 | F3: 3 | G3: 4 | H3: 5 | I3: 6 | J3: 7 | K3: 8 | L3: 9 | M3: 10 | N3: 11 | O3: 12 | P3: 13 | Q3: 14 | R3: 15 | S3: 16 | T3: 17 | U3: 18 | V3: 19 | W3: 20 | X3: 21 | Y3: 22 | Z3: 23 | AA3: 24 | AB3: 25 | AC3: 26 | AD3: 27 | AE3: 28 | AF3: 29 | AG3: 30
A4: CPI index | C4: =(1+Inputs!$C$6)^C3 -> 1 | D4: =(1+Inputs!$C$6)^D3 -> 1.02 | E4: =(1+Inputs!$C$6)^E3 -> 1.0404 | F4: =(1+Inputs!$C$6)^F3 -> 1.061208 | G4: =(1+Inputs!$C$6)^G3 -> 1.0824322 | H4: =(1+Inputs!$C$6)^H3 -> 1.1040808 | I4: =(1+Inputs!$C$6)^I3 -> 1.1261624 | J4: =(1+Inputs!$C$6)^J3 -> 1.1486857 | ... AG4: =(1+Inputs!$C$6)^AG3 -> 1.8113616
A5: Output share | C5: 0 | D5: =Inputs!$C$9 -> 0.8 | E5: 1 | F5: 1 | G5: 1 | H5: 1 | I5: 1 | J5: 1 | K5: 1 | L5: 1 | M5: 1 | N5: 1 | O5: 1 | P5: 1 | Q5: 1 | R5: 1 | S5: 1 | T5: 1 | U5: 1 | V5: 1 | W5: 1 | X5: 1 | Y5: 1 | Z5: 1 | AA5: 1 | AB5: 1 | AC5: 1 | AD5: 1 | AE5: 1 | AF5: 1 | AG5: 1
A6: kg sold | C6: =Inputs!$C$8*Inputs!$C$10*C5 -> 0 | D6: =Inputs!$C$8*Inputs!$C$10*D5 -> 2158474 | E6: =Inputs!$C$8*Inputs!$C$10*E5 -> 2698092.5 | F6: =Inputs!$C$8*Inputs!$C$10*F5 -> 2698092.5 | G6: =Inputs!$C$8*Inputs!$C$10*G5 -> 2698092.5 | H6: =Inputs!$C$8*Inputs!$C$10*H5 -> 2698092.5 | I6: =Inputs!$C$8*Inputs!$C$10*I5 -> 2698092.5 | J6: =Inputs!$C$8*Inputs!$C$10*J5 -> 2698092.5 | ... AG6: =Inputs!$C$8*Inputs!$C$10*AG5 -> 2698092.5
A7: Revenue, real | C7: =Inputs!$C$4*C6 -> 0 | D7: =Inputs!$C$4*D6 -> 3020670.9 | E7: =Inputs!$C$4*E6 -> 3775838.6 | F7: =Inputs!$C$4*F6 -> 3775838.6 | G7: =Inputs!$C$4*G6 -> 3775838.6 | H7: =Inputs!$C$4*H6 -> 3775838.6 | I7: =Inputs!$C$4*I6 -> 3775838.6 | J7: =Inputs!$C$4*J6 -> 3775838.6 | ... AG7: =Inputs!$C$4*AG6 -> 3775838.6
A8: Opex, real | C8: 0 | D8: =SUMIF(Inputs!$D$55:$D$72,"fixed",Inputs!$C$55:$C$72)+SUMIF(Inputs!$D$55:$D$72,"labour",Inputs!$C$55:$C$72)*Inputs!$C$14*((1-Inputs!$C$15)+Inputs!$C$15*Inputs!$C$10)+SUMIF(Inputs!$D$55:$D$72,"elec",Inputs!$C$55:$C$72)*Inputs!$C$12+SUMIF(Inputs!$D$55:$D$72,"co2_purchased",Inputs!$C$55:$C$72)*Inputs!$C$13/0.06+SUMIF(Inputs!$D$55:$D$72,"per_kg",Inputs!$C$55:$C$72)/Inputs!$C$8*D6+SUMIF(Inputs!$D$55:$D$72,"sales_commission",Inputs!$C$55:$C$72)/Inputs!$C$75*D7 -> 1833474.2 | E8: =SUMIF(Inputs!$D$55:$D$72,"fixed",Inputs!$C$55:$C$72)+SUMIF(Inputs!$D$55:$D$72,"labour",Inputs!$C$55:$C$72)*Inputs!$C$14*((1-Inputs!$C$15)+Inputs!$C$15*Inputs!$C$10)+SUMIF(Inputs!$D$55:$D$72,"elec",Inputs!$C$55:$C$72)*Inputs!$C$12+SUMIF(Inputs!$D$55:$D$72,"co2_purchased",Inputs!$C$55:$C$72)*Inputs!$C$13/0.06+SUMIF(Inputs!$D$55:$D$72,"per_kg",Inputs!$C$55:$C$72)/Inputs!$C$8*E6+SUMIF(Inputs!$D$55:$D$72,"sales_commission",Inputs!$C$55:$C$72)/Inputs!$C$75*E7 -> 1860455.2 | F8: =SUMIF(Inputs!$D$55:$D$72,"fixed",Inputs!$C$55:$C$72)+SUMIF(Inputs!$D$55:$D$72,"labour",Inputs!$C$55:$C$72)*Inputs!$C$14*((1-Inputs!$C$15)+Inputs!$C$15*Inputs!$C$10)+SUMIF(Inputs!$D$55:$D$72,"elec",Inputs!$C$55:$C$72)*Inputs!$C$12+SUMIF(Inputs!$D$55:$D$72,"co2_purchased",Inputs!$C$55:$C$72)*Inputs!$C$13/0.06+SUMIF(Inputs!$D$55:$D$72,"per_kg",Inputs!$C$55:$C$72)/Inputs!$C$8*F6+SUMIF(Inputs!$D$55:$D$72,"sales_commission",Inputs!$C$55:$C$72)/Inputs!$C$75*F7 -> 1860455.2 | G8: =SUMIF(Inputs!$D$55:$D$72,"fixed",Inputs!$C$55:$C$72)+SUMIF(Inputs!$D$55:$D$72,"labour",Inputs!$C$55:$C$72)*Inputs!$C$14*((1-Inputs!$C$15)+Inputs!$C$15*Inputs!$C$10)+SUMIF(Inputs!$D$55:$D$72,"elec",Inputs!$C$55:$C$72)*Inputs!$C$12+SUMIF(Inputs!$D$55:$D$72,"co2_purchased",Inputs!$C$55:$C$72)*Inputs!$C$13/0.06+SUMIF(Inputs!$D$55:$D$72,"per_kg",Inputs!$C$55:$C$72)/Inputs!$C$8*G6+SUMIF(Inputs!$D$55:$D$72,"sales_commission",Inputs!$C$55:$C$72)/Inputs!$C$75*G7 -> 1860455.2 | H8: =SUMIF(Inputs!$D$55:$D$72,"fixed",Inputs!$C$55:$C$72)+SUMIF(Inputs!$D$55:$D$72,"labour",Inputs!$C$55:$C$72)*Inputs!$C$14*((1-Inputs!$C$15)+Inputs!$C$15*Inputs!$C$10)+SUMIF(Inputs!$D$55:$D$72,"elec",Inputs!$C$55:$C$72)*Inputs!$C$12+SUMIF(Inputs!$D$55:$D$72,"co2_purchased",Inputs!$C$55:$C$72)*Inputs!$C$13/0.06+SUMIF(Inputs!$D$55:$D$72,"per_kg",Inputs!$C$55:$C$72)/Inputs!$C$8*H6+SUMIF(Inputs!$D$55:$D$72,"sales_commission",Inputs!$C$55:$C$72)/Inputs!$C$75*H7 -> 1860455.2 | I8: =SUMIF(Inputs!$D$55:$D$72,"fixed",Inputs!$C$55:$C$72)+SUMIF(Inputs!$D$55:$D$72,"labour",Inputs!$C$55:$C$72)*Inputs!$C$14*((1-Inputs!$C$15)+Inputs!$C$15*Inputs!$C$10)+SUMIF(Inputs!$D$55:$D$72,"elec",Inputs!$C$55:$C$72)*Inputs!$C$12+SUMIF(Inputs!$D$55:$D$72,"co2_purchased",Inputs!$C$55:$C$72)*Inputs!$C$13/0.06+SUMIF(Inputs!$D$55:$D$72,"per_kg",Inputs!$C$55:$C$72)/Inputs!$C$8*I6+SUMIF(Inputs!$D$55:$D$72,"sales_commission",Inputs!$C$55:$C$72)/Inputs!$C$75*I7 -> 1860455.2 | J8: =SUMIF(Inputs!$D$55:$D$72,"fixed",Inputs!$C$55:$C$72)+SUMIF(Inputs!$D$55:$D$72,"labour",Inputs!$C$55:$C$72)*Inputs!$C$14*((1-Inputs!$C$15)+Inputs!$C$15*Inputs!$C$10)+SUMIF(Inputs!$D$55:$D$72,"elec",Inputs!$C$55:$C$72)*Inputs!$C$12+SUMIF(Inputs!$D$55:$D$72,"co2_purchased",Inputs!$C$55:$C$72)*Inputs!$C$13/0.06+SUMIF(Inputs!$D$55:$D$72,"per_kg",Inputs!$C$55:$C$72)/Inputs!$C$8*J6+SUMIF(Inputs!$D$55:$D$72,"sales_commission",Inputs!$C$55:$C$72)/Inputs!$C$75*J7 -> 1860455.2 | K8: =SUMIF(Inputs!$D$55:$D$72,"fixed",Inputs!$C$55:$C$72)+SUMIF(Inputs!$D$55:$D$72,"labour",Inputs!$C$55:$C$72)*Inputs!$C$14*((1-Inputs!$C$15)+Inputs!$C$15*Inputs!$C$10)+SUMIF(Inputs!$D$55:$D$72,"elec",Inputs!$C$55:$C$72)*Inputs!$C$12+SUMIF(Inputs!$D$55:$D$72,"co2_purchased",Inputs!$C$55:$C$72)*Inputs!$C$13/0.06+SUMIF(Inputs!$D$55:$D$72,"per_kg",Inputs!$C$55:$C$72)/Inputs!$C$8*K6+SUMIF(Inputs!$D$55:$D$72,"sales_commission",Inputs!$C$55:$C$72)/Inputs!$C$75*K7 -> 1860455.2 | ... AG8: =SUMIF(Inputs!$D$55:$D$72,"fixed",Inputs!$C$55:$C$72)+SUMIF(Inputs!$D$55:$D$72,"labour",Inputs!$C$55:$C$72)*Inputs!$C$14*((1-Inputs!$C$15)+Inputs!$C$15*Inputs!$C$10)+SUMIF(Inputs!$D$55:$D$72,"elec",Inputs!$C$55:$C$72)*Inputs!$C$12+SUMIF(Inputs!$D$55:$D$72,"co2_purchased",Inputs!$C$55:$C$72)*Inputs!$C$13/0.06+SUMIF(Inputs!$D$55:$D$72,"per_kg",Inputs!$C$55:$C$72)/Inputs!$C$8*AG6+SUMIF(Inputs!$D$55:$D$72,"sales_commission",Inputs!$C$55:$C$72)/Inputs!$C$75*AG7 -> 1860455.2
A9: Replacement capex, real | C9: =Inputs!E79*Inputs!$C$11 -> 0 | D9: =Inputs!F79*Inputs!$C$11 -> 2.3283064e-10 | E9: =Inputs!G79*Inputs!$C$11 -> 0 | F9: =Inputs!H79*Inputs!$C$11 -> 0 | G9: =Inputs!I79*Inputs!$C$11 -> 0 | H9: =Inputs!J79*Inputs!$C$11 -> 0 | I9: =Inputs!K79*Inputs!$C$11 -> 0 | J9: =Inputs!L79*Inputs!$C$11 -> 0 | ... AG9: =Inputs!AI79*Inputs!$C$11 -> 0
A10: Unlevered cash flow, real pre-tax | C10: =-SUM(Inputs!$C$36:$C$52)*Inputs!$C$11 -> -11453365 | D10: =D7-D8-D9 -> 1187196.7 | E10: =E7-E8-E9 -> 1915383.5 | F10: =F7-F8-F9 -> 1915383.5 | G10: =G7-G8-G9 -> 1915383.5 | H10: =H7-H8-H9 -> 1915383.5 | I10: =I7-I8-I9 -> 1915383.5 | J10: =J7-J8-J9 -> 1915383.5 | K10: =K7-K8-K9 -> 1915383.5 | ... AF10: =AF7-AF8-AF9 -> 1915383.5 | AG10: =AG7-AG8-AG9+Inputs!$C$74*Inputs!$C$11 -> 3993320.2
A11: EBITDA, nominal | C11: =(C7-C8)*C4 -> 0 | D11: =(D7-D8)*D4 -> 1210940.6 | E11: =(E7-E8)*E4 -> 1992765 | F11: =(F7-F8)*F4 -> 2032620.3 | G11: =(G7-G8)*G4 -> 2073272.7 | H11: =(H7-H8)*H4 -> 2114738.1 | I11: =(I7-I8)*I4 -> 2157032.9 | J11: =(J7-J8)*J4 -> 2200173.5 | ... AG11: =(AG7-AG8)*AG4 -> 3469452
A12: Opex, nominal | C12: =C8*C4 -> 0 | D12: =D8*D4 -> 1870143.7 | E12: =E8*E4 -> 1935617.6 | F12: =F8*F4 -> 1974329.9 | G12: =G8*G4 -> 2013816.5 | H12: =H8*H4 -> 2054092.8 | I12: =I8*I4 -> 2095174.7 | J12: =J8*J4 -> 2137078.2 | ... AG12: =AG8*AG4 -> 3369957
A13: Replacements, nominal | C13: =C9*C4 -> 0 | D13: =D9*D4 -> 2.3748726e-10 | E13: =E9*E4 -> 0 | F13: =F9*F4 -> 0 | G13: =G9*G4 -> 0 | H13: =H9*H4 -> 0 | I13: =I9*I4 -> 0 | J13: =J9*J4 -> 0 | ... AG13: =AG9*AG4 -> 0
A14: Residual value, nominal | C14: 0 | D14: 0 | E14: 0 | F14: 0 | G14: 0 | H14: 0 | I14: 0 | J14: 0 | K14: 0 | L14: 0 | M14: 0 | N14: 0 | O14: 0 | P14: 0 | Q14: 0 | R14: 0 | S14: 0 | T14: 0 | U14: 0 | V14: 0 | W14: 0 | X14: 0 | Y14: 0 | Z14: 0 | AA14: 0 | AB14: 0 | AC14: 0 | AD14: 0 | AE14: 0 | AF14: 0 | AG14: =Inputs!$C$74*Inputs!$C$11*AG4 -> 3763894.8
A15: Special-rate pool additions | C15: =SUMIF(Inputs!$D$36:$D$52,"special",Inputs!$C$36:$C$52)*Inputs!$C$11*(1+SUMIF(Inputs!$D$36:$D$52,"contingency",Inputs!$C$36:$C$52)*Inputs!$C$11/(SUMIF(Inputs!$D$36:$D$52,"main",Inputs!$C$36:$C$52)*Inputs!$C$11+SUMIF(Inputs!$D$36:$D$52,"special",Inputs!$C$36:$C$52)*Inputs!$C$11))*(1-Inputs!$C$26/(SUMIF(Inputs!$D$36:$D$52,"main",Inputs!$C$36:$C$52)*Inputs!$C$11+SUMIF(Inputs!$D$36:$D$52,"special",Inputs!$C$36:$C$52)*Inputs!$C$11+SUMIF(Inputs!$D$36:$D$52,"contingency",Inputs!$C$36:$C$52)*Inputs!$C$11)) -> 5364026.8 | D15: =D13 -> 2.3748726e-10 | E15: =E13 -> 0 | F15: =F13 -> 0 | G15: =G13 -> 0 | H15: =H13 -> 0 | I15: =I13 -> 0 | J15: =J13 -> 0 | K15: =K13 -> 0 | ... AG15: =AG13 -> 0
A16: First-year allowance (special) | C16: =Inputs!$C$32*C15 -> 2682013.4 | D16: =Inputs!$C$32*D15 -> 1.1874363e-10 | E16: =Inputs!$C$32*E15 -> 0 | F16: =Inputs!$C$32*F15 -> 0 | G16: =Inputs!$C$32*G15 -> 0 | H16: =Inputs!$C$32*H15 -> 0 | I16: =Inputs!$C$32*I15 -> 0 | J16: =Inputs!$C$32*J15 -> 0 | ... AG16: =Inputs!$C$32*AG15 -> 0
A17: Writing-down allowance (special) | C17: =Inputs!$C$33*(0+C15-C16) -> 160920.8 | D17: =Inputs!$C$33*(C18+D15-D16) -> 151265.55 | E17: =Inputs!$C$33*(D18+E15-E16) -> 142189.62 | F17: =Inputs!$C$33*(E18+F15-F16) -> 133658.24 | G17: =Inputs!$C$33*(F18+G15-G16) -> 125638.75 | H17: =Inputs!$C$33*(G18+H15-H16) -> 118100.42 | I17: =Inputs!$C$33*(H18+I15-I16) -> 111014.4 | J17: =Inputs!$C$33*(I18+J15-J16) -> 104353.54 | K17: =Inputs!$C$33*(J18+K15-K16) -> 98092.323 | ... AG17: =Inputs!$C$33*(AF18+AG15-AG16) -> 151894.61
A18: Special-rate pool, closing | C18: =0+C15-C16-C17 -> 2521092.6 | D18: =C18+D15-D16-D17 -> 2369827 | E18: =D18+E15-E16-E17 -> 2227637.4 | F18: =E18+F15-F16-F17 -> 2093979.2 | G18: =F18+G15-G16-G17 -> 1968340.4 | H18: =G18+H15-H16-H17 -> 1850240 | I18: =H18+I15-I16-I17 -> 1739225.6 | J18: =I18+J15-J16-J17 -> 1634872.1 | K18: =J18+K15-K16-K17 -> 1536779.7 | ... AG18: =AF18+AG15-AG16-AG17 -> 2379682.2
A19: Capital allowances | C19: =(SUMIF(Inputs!$D$36:$D$52,"main",Inputs!$C$36:$C$52)*Inputs!$C$11+SUMIF(Inputs!$D$36:$D$52,"special",Inputs!$C$36:$C$52)*Inputs!$C$11+SUMIF(Inputs!$D$36:$D$52,"contingency",Inputs!$C$36:$C$52)*Inputs!$C$11)*(1-Inputs!$C$26/(SUMIF(Inputs!$D$36:$D$52,"main",Inputs!$C$36:$C$52)*Inputs!$C$11+SUMIF(Inputs!$D$36:$D$52,"special",Inputs!$C$36:$C$52)*Inputs!$C$11+SUMIF(Inputs!$D$36:$D$52,"contingency",Inputs!$C$36:$C$52)*Inputs!$C$11))-C15+C16+C17 -> 7800399.6 | D19: =D16+D17 -> 151265.55 | E19: =E16+E17 -> 142189.62 | F19: =F16+F17 -> 133658.24 | G19: =G16+G17 -> 125638.75 | H19: =H16+H17 -> 118100.42 | I19: =I16+I17 -> 111014.4 | J19: =J16+J17 -> 104353.54 | K19: =K16+K17 -> 98092.323 | ... AF19: =AF16+AF17 -> 161590.01 | AG19: =AG16+AG17+AG18-AG14 -> -1232318
A20: ECA supplier credit, closing balance | B20: =C20 -> 4694641.9 | C20: =SUMIF(Inputs!$B$36:$B$52,"ECA",Inputs!$C$36:$C$52)*Inputs!$C$11*Inputs!$C$16 -> 4694641.9 | D20: =C20-D22 -> 4694641.9 | E20: =D20-E22 -> 4359310.3 | F20: =E20-F22 -> 4023978.8 | G20: =F20-G22 -> 3688647.2 | H20: =G20-H22 -> 3353315.6 | I20: =H20-I22 -> 3017984.1 | J20: =I20-J22 -> 2682652.5 | K20: =J20-K22 -> 2347320.9 | ... AG20: =AF20-AG22 -> 0
A21: ECA interest | C21: 0 | D21: =IF(1<=Inputs!$C$18,C20*Inputs!$C$17,0) -> 272758.69 | E21: =IF(2<=Inputs!$C$18,D20*Inputs!$C$17,0) -> 272758.69 | F21: =IF(3<=Inputs!$C$18,E20*Inputs!$C$17,0) -> 253275.93 | G21: =IF(4<=Inputs!$C$18,F20*Inputs!$C$17,0) -> 233793.17 | H21: =IF(5<=Inputs!$C$18,G20*Inputs!$C$17,0) -> 214310.4 | I21: =IF(6<=Inputs!$C$18,H20*Inputs!$C$17,0) -> 194827.64 | J21: =IF(7<=Inputs!$C$18,I20*Inputs!$C$17,0) -> 175344.87 | K21: =IF(8<=Inputs!$C$18,J20*Inputs!$C$17,0) -> 155862.11 | L21: =IF(9<=Inputs!$C$18,K20*Inputs!$C$17,0) -> 136379.35 | M21: =IF(10<=Inputs!$C$18,L20*Inputs!$C$17,0) -> 116896.58 | N21: =IF(11<=Inputs!$C$18,M20*Inputs!$C$17,0) -> 97413.819 | O21: =IF(12<=Inputs!$C$18,N20*Inputs!$C$17,0) -> 77931.055 | P21: =IF(13<=Inputs!$C$18,O20*Inputs!$C$17,0) -> 58448.292 | Q21: =IF(14<=Inputs!$C$18,P20*Inputs!$C$17,0) -> 38965.528 | R21: =IF(15<=Inputs!$C$18,Q20*Inputs!$C$17,0) -> 19482.764 | S21: =IF(16<=Inputs!$C$18,R20*Inputs!$C$17,0) -> 0 | T21: =IF(17<=Inputs!$C$18,S20*Inputs!$C$17,0) -> 0 | U21: =IF(18<=Inputs!$C$18,T20*Inputs!$C$17,0) -> 0 | V21: =IF(19<=Inputs!$C$18,U20*Inputs!$C$17,0) -> 0 | W21: =IF(20<=Inputs!$C$18,V20*Inputs!$C$17,0) -> 0 | X21: =IF(21<=Inputs!$C$18,W20*Inputs!$C$17,0) -> 0 | Y21: =IF(22<=Inputs!$C$18,X20*Inputs!$C$17,0) -> 0 | Z21: =IF(23<=Inputs!$C$18,Y20*Inputs!$C$17,0) -> 0 | AA21: =IF(24<=Inputs!$C$18,Z20*Inputs!$C$17,0) -> 0 | AB21: =IF(25<=Inputs!$C$18,AA20*Inputs!$C$17,0) -> 0 | AC21: =IF(26<=Inputs!$C$18,AB20*Inputs!$C$17,0) -> 0 | AD21: =IF(27<=Inputs!$C$18,AC20*Inputs!$C$17,0) -> 0 | AE21: =IF(28<=Inputs!$C$18,AD20*Inputs!$C$17,0) -> 0 | AF21: =IF(29<=Inputs!$C$18,AE20*Inputs!$C$17,0) -> 0 | AG21: =IF(30<=Inputs!$C$18,AF20*Inputs!$C$17,0) -> 0
A22: ECA principal (equal instalments) | C22: 0 | D22: =IF(AND(1>Inputs!$C$19,1<=Inputs!$C$18),MIN($B20/(Inputs!$C$18-Inputs!$C$19),C20),0) -> 0 | E22: =IF(AND(2>Inputs!$C$19,2<=Inputs!$C$18),MIN($B20/(Inputs!$C$18-Inputs!$C$19),D20),0) -> 335331.56 | F22: =IF(AND(3>Inputs!$C$19,3<=Inputs!$C$18),MIN($B20/(Inputs!$C$18-Inputs!$C$19),E20),0) -> 335331.56 | G22: =IF(AND(4>Inputs!$C$19,4<=Inputs!$C$18),MIN($B20/(Inputs!$C$18-Inputs!$C$19),F20),0) -> 335331.56 | H22: =IF(AND(5>Inputs!$C$19,5<=Inputs!$C$18),MIN($B20/(Inputs!$C$18-Inputs!$C$19),G20),0) -> 335331.56 | I22: =IF(AND(6>Inputs!$C$19,6<=Inputs!$C$18),MIN($B20/(Inputs!$C$18-Inputs!$C$19),H20),0) -> 335331.56 | J22: =IF(AND(7>Inputs!$C$19,7<=Inputs!$C$18),MIN($B20/(Inputs!$C$18-Inputs!$C$19),I20),0) -> 335331.56 | K22: =IF(AND(8>Inputs!$C$19,8<=Inputs!$C$18),MIN($B20/(Inputs!$C$18-Inputs!$C$19),J20),0) -> 335331.56 | L22: =IF(AND(9>Inputs!$C$19,9<=Inputs!$C$18),MIN($B20/(Inputs!$C$18-Inputs!$C$19),K20),0) -> 335331.56 | M22: =IF(AND(10>Inputs!$C$19,10<=Inputs!$C$18),MIN($B20/(Inputs!$C$18-Inputs!$C$19),L20),0) -> 335331.56 | N22: =IF(AND(11>Inputs!$C$19,11<=Inputs!$C$18),MIN($B20/(Inputs!$C$18-Inputs!$C$19),M20),0) -> 335331.56 | O22: =IF(AND(12>Inputs!$C$19,12<=Inputs!$C$18),MIN($B20/(Inputs!$C$18-Inputs!$C$19),N20),0) -> 335331.56 | P22: =IF(AND(13>Inputs!$C$19,13<=Inputs!$C$18),MIN($B20/(Inputs!$C$18-Inputs!$C$19),O20),0) -> 335331.56 | Q22: =IF(AND(14>Inputs!$C$19,14<=Inputs!$C$18),MIN($B20/(Inputs!$C$18-Inputs!$C$19),P20),0) -> 335331.56 | R22: =IF(AND(15>Inputs!$C$19,15<=Inputs!$C$18),MIN($B20/(Inputs!$C$18-Inputs!$C$19),Q20),0) -> 335331.56 | S22: =IF(AND(16>Inputs!$C$19,16<=Inputs!$C$18),MIN($B20/(Inputs!$C$18-Inputs!$C$19),R20),0) -> 0 | T22: =IF(AND(17>Inputs!$C$19,17<=Inputs!$C$18),MIN($B20/(Inputs!$C$18-Inputs!$C$19),S20),0) -> 0 | U22: =IF(AND(18>Inputs!$C$19,18<=Inputs!$C$18),MIN($B20/(Inputs!$C$18-Inputs!$C$19),T20),0) -> 0 | V22: =IF(AND(19>Inputs!$C$19,19<=Inputs!$C$18),MIN($B20/(Inputs!$C$18-Inputs!$C$19),U20),0) -> 0 | W22: =IF(AND(20>Inputs!$C$19,20<=Inputs!$C$18),MIN($B20/(Inputs!$C$18-Inputs!$C$19),V20),0) -> 0 | X22: =IF(AND(21>Inputs!$C$19,21<=Inputs!$C$18),MIN($B20/(Inputs!$C$18-Inputs!$C$19),W20),0) -> 0 | Y22: =IF(AND(22>Inputs!$C$19,22<=Inputs!$C$18),MIN($B20/(Inputs!$C$18-Inputs!$C$19),X20),0) -> 0 | Z22: =IF(AND(23>Inputs!$C$19,23<=Inputs!$C$18),MIN($B20/(Inputs!$C$18-Inputs!$C$19),Y20),0) -> 0 | AA22: =IF(AND(24>Inputs!$C$19,24<=Inputs!$C$18),MIN($B20/(Inputs!$C$18-Inputs!$C$19),Z20),0) -> 0 | AB22: =IF(AND(25>Inputs!$C$19,25<=Inputs!$C$18),MIN($B20/(Inputs!$C$18-Inputs!$C$19),AA20),0) -> 0 | AC22: =IF(AND(26>Inputs!$C$19,26<=Inputs!$C$18),MIN($B20/(Inputs!$C$18-Inputs!$C$19),AB20),0) -> 0 | AD22: =IF(AND(27>Inputs!$C$19,27<=Inputs!$C$18),MIN($B20/(Inputs!$C$18-Inputs!$C$19),AC20),0) -> 0 | AE22: =IF(AND(28>Inputs!$C$19,28<=Inputs!$C$18),MIN($B20/(Inputs!$C$18-Inputs!$C$19),AD20),0) -> 0 | AF22: =IF(AND(29>Inputs!$C$19,29<=Inputs!$C$18),MIN($B20/(Inputs!$C$18-Inputs!$C$19),AE20),0) -> 0 | AG22: =IF(AND(30>Inputs!$C$19,30<=Inputs!$C$18),MIN($B20/(Inputs!$C$18-Inputs!$C$19),AF20),0) -> 0
A23: Plant asset finance, closing balance | B23: =C23 -> 3422195.4 | C23: =SUMIF(Inputs!$B$36:$B$52,"AF",Inputs!$C$36:$C$52)*Inputs!$C$11*Inputs!$C$21 -> 3422195.4 | D23: =C23-D25 -> 3422195.4 | E23: =D23-E25 -> 3136488.4 | F23: =E23-F25 -> 2830781.9 | G23: =F23-G25 -> 2503675.9 | H23: =G23-H25 -> 2153672.6 | I23: =H23-I25 -> 1779168.9 | J23: =I23-J25 -> 1378450.1 | K23: =J23-K25 -> 949680.88 | ... AG23: =AF23-AG25 -> 3.085006e-09
A24: Asset finance interest | C24: 0 | D24: =IF(1<=Inputs!$C$23,C23*Inputs!$C$22,0) -> 239553.68 | E24: =IF(2<=Inputs!$C$23,D23*Inputs!$C$22,0) -> 239553.68 | F24: =IF(3<=Inputs!$C$23,E23*Inputs!$C$22,0) -> 219554.19 | G24: =IF(4<=Inputs!$C$23,F23*Inputs!$C$22,0) -> 198154.73 | H24: =IF(5<=Inputs!$C$23,G23*Inputs!$C$22,0) -> 175257.32 | I24: =IF(6<=Inputs!$C$23,H23*Inputs!$C$22,0) -> 150757.08 | J24: =IF(7<=Inputs!$C$23,I23*Inputs!$C$22,0) -> 124541.83 | K24: =IF(8<=Inputs!$C$23,J23*Inputs!$C$22,0) -> 96491.505 | L24: =IF(9<=Inputs!$C$23,K23*Inputs!$C$22,0) -> 66477.662 | M24: =IF(10<=Inputs!$C$23,L23*Inputs!$C$22,0) -> 34362.849 | N24: =IF(11<=Inputs!$C$23,M23*Inputs!$C$22,0) -> 0 | O24: =IF(12<=Inputs!$C$23,N23*Inputs!$C$22,0) -> 0 | P24: =IF(13<=Inputs!$C$23,O23*Inputs!$C$22,0) -> 0 | Q24: =IF(14<=Inputs!$C$23,P23*Inputs!$C$22,0) -> 0 | R24: =IF(15<=Inputs!$C$23,Q23*Inputs!$C$22,0) -> 0 | S24: =IF(16<=Inputs!$C$23,R23*Inputs!$C$22,0) -> 0 | T24: =IF(17<=Inputs!$C$23,S23*Inputs!$C$22,0) -> 0 | U24: =IF(18<=Inputs!$C$23,T23*Inputs!$C$22,0) -> 0 | V24: =IF(19<=Inputs!$C$23,U23*Inputs!$C$22,0) -> 0 | W24: =IF(20<=Inputs!$C$23,V23*Inputs!$C$22,0) -> 0 | X24: =IF(21<=Inputs!$C$23,W23*Inputs!$C$22,0) -> 0 | Y24: =IF(22<=Inputs!$C$23,X23*Inputs!$C$22,0) -> 0 | Z24: =IF(23<=Inputs!$C$23,Y23*Inputs!$C$22,0) -> 0 | AA24: =IF(24<=Inputs!$C$23,Z23*Inputs!$C$22,0) -> 0 | AB24: =IF(25<=Inputs!$C$23,AA23*Inputs!$C$22,0) -> 0 | AC24: =IF(26<=Inputs!$C$23,AB23*Inputs!$C$22,0) -> 0 | AD24: =IF(27<=Inputs!$C$23,AC23*Inputs!$C$22,0) -> 0 | AE24: =IF(28<=Inputs!$C$23,AD23*Inputs!$C$22,0) -> 0 | AF24: =IF(29<=Inputs!$C$23,AE23*Inputs!$C$22,0) -> 0 | AG24: =IF(30<=Inputs!$C$23,AF23*Inputs!$C$22,0) -> 0
A25: Asset finance principal (annuity) | C25: 0 | D25: =IF(AND(1>Inputs!$C$24,1<=Inputs!$C$23),MIN($B23*Inputs!$C$22/(1-(1+Inputs!$C$22)^-(Inputs!$C$23-Inputs!$C$24))-D24,C23),0) -> 0 | E25: =IF(AND(2>Inputs!$C$24,2<=Inputs!$C$23),MIN($B23*Inputs!$C$22/(1-(1+Inputs!$C$22)^-(Inputs!$C$23-Inputs!$C$24))-E24,D23),0) -> 285707.02 | F25: =IF(AND(3>Inputs!$C$24,3<=Inputs!$C$23),MIN($B23*Inputs!$C$22/(1-(1+Inputs!$C$22)^-(Inputs!$C$23-Inputs!$C$24))-F24,E23),0) -> 305706.51 | G25: =IF(AND(4>Inputs!$C$24,4<=Inputs!$C$23),MIN($B23*Inputs!$C$22/(1-(1+Inputs!$C$22)^-(Inputs!$C$23-Inputs!$C$24))-G24,F23),0) -> 327105.96 | H25: =IF(AND(5>Inputs!$C$24,5<=Inputs!$C$23),MIN($B23*Inputs!$C$22/(1-(1+Inputs!$C$22)^-(Inputs!$C$23-Inputs!$C$24))-H24,G23),0) -> 350003.38 | I25: =IF(AND(6>Inputs!$C$24,6<=Inputs!$C$23),MIN($B23*Inputs!$C$22/(1-(1+Inputs!$C$22)^-(Inputs!$C$23-Inputs!$C$24))-I24,H23),0) -> 374503.62 | J25: =IF(AND(7>Inputs!$C$24,7<=Inputs!$C$23),MIN($B23*Inputs!$C$22/(1-(1+Inputs!$C$22)^-(Inputs!$C$23-Inputs!$C$24))-J24,I23),0) -> 400718.87 | K25: =IF(AND(8>Inputs!$C$24,8<=Inputs!$C$23),MIN($B23*Inputs!$C$22/(1-(1+Inputs!$C$22)^-(Inputs!$C$23-Inputs!$C$24))-K24,J23),0) -> 428769.19 | L25: =IF(AND(9>Inputs!$C$24,9<=Inputs!$C$23),MIN($B23*Inputs!$C$22/(1-(1+Inputs!$C$22)^-(Inputs!$C$23-Inputs!$C$24))-L24,K23),0) -> 458783.04 | M25: =IF(AND(10>Inputs!$C$24,10<=Inputs!$C$23),MIN($B23*Inputs!$C$22/(1-(1+Inputs!$C$22)^-(Inputs!$C$23-Inputs!$C$24))-M24,L23),0) -> 490897.85 | N25: =IF(AND(11>Inputs!$C$24,11<=Inputs!$C$23),MIN($B23*Inputs!$C$22/(1-(1+Inputs!$C$22)^-(Inputs!$C$23-Inputs!$C$24))-N24,M23),0) -> 0 | O25: =IF(AND(12>Inputs!$C$24,12<=Inputs!$C$23),MIN($B23*Inputs!$C$22/(1-(1+Inputs!$C$22)^-(Inputs!$C$23-Inputs!$C$24))-O24,N23),0) -> 0 | P25: =IF(AND(13>Inputs!$C$24,13<=Inputs!$C$23),MIN($B23*Inputs!$C$22/(1-(1+Inputs!$C$22)^-(Inputs!$C$23-Inputs!$C$24))-P24,O23),0) -> 0 | Q25: =IF(AND(14>Inputs!$C$24,14<=Inputs!$C$23),MIN($B23*Inputs!$C$22/(1-(1+Inputs!$C$22)^-(Inputs!$C$23-Inputs!$C$24))-Q24,P23),0) -> 0 | R25: =IF(AND(15>Inputs!$C$24,15<=Inputs!$C$23),MIN($B23*Inputs!$C$22/(1-(1+Inputs!$C$22)^-(Inputs!$C$23-Inputs!$C$24))-R24,Q23),0) -> 0 | S25: =IF(AND(16>Inputs!$C$24,16<=Inputs!$C$23),MIN($B23*Inputs!$C$22/(1-(1+Inputs!$C$22)^-(Inputs!$C$23-Inputs!$C$24))-S24,R23),0) -> 0 | T25: =IF(AND(17>Inputs!$C$24,17<=Inputs!$C$23),MIN($B23*Inputs!$C$22/(1-(1+Inputs!$C$22)^-(Inputs!$C$23-Inputs!$C$24))-T24,S23),0) -> 0 | U25: =IF(AND(18>Inputs!$C$24,18<=Inputs!$C$23),MIN($B23*Inputs!$C$22/(1-(1+Inputs!$C$22)^-(Inputs!$C$23-Inputs!$C$24))-U24,T23),0) -> 0 | V25: =IF(AND(19>Inputs!$C$24,19<=Inputs!$C$23),MIN($B23*Inputs!$C$22/(1-(1+Inputs!$C$22)^-(Inputs!$C$23-Inputs!$C$24))-V24,U23),0) -> 0 | W25: =IF(AND(20>Inputs!$C$24,20<=Inputs!$C$23),MIN($B23*Inputs!$C$22/(1-(1+Inputs!$C$22)^-(Inputs!$C$23-Inputs!$C$24))-W24,V23),0) -> 0 | X25: =IF(AND(21>Inputs!$C$24,21<=Inputs!$C$23),MIN($B23*Inputs!$C$22/(1-(1+Inputs!$C$22)^-(Inputs!$C$23-Inputs!$C$24))-X24,W23),0) -> 0 | Y25: =IF(AND(22>Inputs!$C$24,22<=Inputs!$C$23),MIN($B23*Inputs!$C$22/(1-(1+Inputs!$C$22)^-(Inputs!$C$23-Inputs!$C$24))-Y24,X23),0) -> 0 | Z25: =IF(AND(23>Inputs!$C$24,23<=Inputs!$C$23),MIN($B23*Inputs!$C$22/(1-(1+Inputs!$C$22)^-(Inputs!$C$23-Inputs!$C$24))-Z24,Y23),0) -> 0 | AA25: =IF(AND(24>Inputs!$C$24,24<=Inputs!$C$23),MIN($B23*Inputs!$C$22/(1-(1+Inputs!$C$22)^-(Inputs!$C$23-Inputs!$C$24))-AA24,Z23),0) -> 0 | AB25: =IF(AND(25>Inputs!$C$24,25<=Inputs!$C$23),MIN($B23*Inputs!$C$22/(1-(1+Inputs!$C$22)^-(Inputs!$C$23-Inputs!$C$24))-AB24,AA23),0) -> 0 | AC25: =IF(AND(26>Inputs!$C$24,26<=Inputs!$C$23),MIN($B23*Inputs!$C$22/(1-(1+Inputs!$C$22)^-(Inputs!$C$23-Inputs!$C$24))-AC24,AB23),0) -> 0 | AD25: =IF(AND(27>Inputs!$C$24,27<=Inputs!$C$23),MIN($B23*Inputs!$C$22/(1-(1+Inputs!$C$22)^-(Inputs!$C$23-Inputs!$C$24))-AD24,AC23),0) -> 0 | AE25: =IF(AND(28>Inputs!$C$24,28<=Inputs!$C$23),MIN($B23*Inputs!$C$22/(1-(1+Inputs!$C$22)^-(Inputs!$C$23-Inputs!$C$24))-AE24,AD23),0) -> 0 | AF25: =IF(AND(29>Inputs!$C$24,29<=Inputs!$C$23),MIN($B23*Inputs!$C$22/(1-(1+Inputs!$C$22)^-(Inputs!$C$23-Inputs!$C$24))-AF24,AE23),0) -> 0 | AG25: =IF(AND(30>Inputs!$C$24,30<=Inputs!$C$23),MIN($B23*Inputs!$C$22/(1-(1+Inputs!$C$22)^-(Inputs!$C$23-Inputs!$C$24))-AG24,AF23),0) -> 0
A26: Debt service | C26: =C21+C22+C24+C25 -> 0 | D26: =D21+D22+D24+D25 -> 512312.37 | E26: =E21+E22+E24+E25 -> 1133351 | F26: =F21+F22+F24+F25 -> 1113868.2 | G26: =G21+G22+G24+G25 -> 1094385.4 | H26: =H21+H22+H24+H25 -> 1074902.7 | I26: =I21+I22+I24+I25 -> 1055419.9 | J26: =J21+J22+J24+J25 -> 1035937.1 | ... AG26: =AG21+AG22+AG24+AG25 -> 0
A27: Taxable profit before losses | C27: =C11-C19-C21-C24 -> -7800399.6 | D27: =D11-D19-D21-D24 -> 547362.68 | E27: =E11-E19-E21-E24 -> 1338263 | F27: =F11-F19-F21-F24 -> 1426131.9 | G27: =G11-G19-G21-G24 -> 1515686 | H27: =H11-H19-H21-H24 -> 1607070 | I27: =I11-I19-I21-I24 -> 1700433.8 | J27: =J11-J19-J21-J24 -> 1795933.3 | ... AG27: =AG11-AG19-AG21-AG24 -> 4701770.1
A28: Losses used | C28: 0 | D28: =MIN(C29,MAX(D27,0)) -> 547362.68 | E28: =MIN(D29,MAX(E27,0)) -> 1338263 | F28: =MIN(E29,MAX(F27,0)) -> 1426131.9 | G28: =MIN(F29,MAX(G27,0)) -> 1515686 | H28: =MIN(G29,MAX(H27,0)) -> 1607070 | I28: =MIN(H29,MAX(I27,0)) -> 1365886.1 | J28: =MIN(I29,MAX(J27,0)) -> 0 | K28: =MIN(J29,MAX(K27,0)) -> 0 | ... AG28: =MIN(AF29,MAX(AG27,0)) -> 0
A29: Losses carried forward | C29: =0-C28+MAX(-C27,0) -> 7800399.6 | D29: =C29-D28+MAX(-D27,0) -> 7253037 | E29: =D29-E28+MAX(-E27,0) -> 5914774 | F29: =E29-F28+MAX(-F27,0) -> 4488642.1 | G29: =F29-G28+MAX(-G27,0) -> 2972956.1 | H29: =G29-H28+MAX(-H27,0) -> 1365886.1 | I29: =H29-I28+MAX(-I27,0) -> 0 | J29: =I29-J28+MAX(-J27,0) -> 0 | K29: =J29-K28+MAX(-K27,0) -> 0 | ... AG29: =AF29-AG28+MAX(-AG27,0) -> 0
A30: Corporation tax paid | C30: =Inputs!$C$7*(MAX(C27,0)-C28) -> 0 | D30: =Inputs!$C$7*(MAX(D27,0)-D28) -> 0 | E30: =Inputs!$C$7*(MAX(E27,0)-E28) -> 0 | F30: =Inputs!$C$7*(MAX(F27,0)-F28) -> 0 | G30: =Inputs!$C$7*(MAX(G27,0)-G28) -> 0 | H30: =Inputs!$C$7*(MAX(H27,0)-H28) -> 0 | I30: =Inputs!$C$7*(MAX(I27,0)-I28) -> 83636.925 | J30: =Inputs!$C$7*(MAX(J27,0)-J28) -> 448983.33 | ... AG30: =Inputs!$C$7*(MAX(AG27,0)-AG28) -> 1175442.5
A31: Working capital balance | C31: =Inputs!$C$29/12*D12 -> 311690.62 | D31: =Inputs!$C$29/12*E12 -> 322602.93 | E31: =Inputs!$C$29/12*F12 -> 329054.98 | F31: =Inputs!$C$29/12*G12 -> 335636.08 | G31: =Inputs!$C$29/12*H12 -> 342348.81 | H31: =Inputs!$C$29/12*I12 -> 349195.78 | I31: =Inputs!$C$29/12*J12 -> 356179.7 | J31: =Inputs!$C$29/12*K12 -> 363303.29 | ... AF31: =Inputs!$C$29/12*AG12 -> 561659.5 | AG31: 0
A32: Working-capital build | C32: =C31-0 -> 311690.62 | D32: =D31-C31 -> 10912.305 | E32: =E31-D31 -> 6452.0585 | F32: =F31-E31 -> 6581.0997 | G32: =G31-F31 -> 6712.7217 | H32: =H31-G31 -> 6846.9761 | I32: =I31-H31 -> 6983.9156 | J32: =J31-I31 -> 7123.594 | K32: =K31-J31 -> 7266.0658 | ... AG32: =AG31-AF31 -> -561659.5
A33: Maintenance reserve | C33: 0 | D33: =NPV(Inputs!$C$31,$D$9:$AG$9)*Inputs!$C$31/(1-(1+Inputs!$C$31)^-30)*D4 -> 111302.32 | E33: =NPV(Inputs!$C$31,$D$9:$AG$9)*Inputs!$C$31/(1-(1+Inputs!$C$31)^-30)*E4 -> 113528.37 | F33: =NPV(Inputs!$C$31,$D$9:$AG$9)*Inputs!$C$31/(1-(1+Inputs!$C$31)^-30)*F4 -> 115798.93 | G33: =NPV(Inputs!$C$31,$D$9:$AG$9)*Inputs!$C$31/(1-(1+Inputs!$C$31)^-30)*G4 -> 118114.91 | H33: =NPV(Inputs!$C$31,$D$9:$AG$9)*Inputs!$C$31/(1-(1+Inputs!$C$31)^-30)*H4 -> 120477.21 | I33: =NPV(Inputs!$C$31,$D$9:$AG$9)*Inputs!$C$31/(1-(1+Inputs!$C$31)^-30)*I4 -> 122886.75 | J33: =NPV(Inputs!$C$31,$D$9:$AG$9)*Inputs!$C$31/(1-(1+Inputs!$C$31)^-30)*J4 -> 125344.49 | K33: =NPV(Inputs!$C$31,$D$9:$AG$9)*Inputs!$C$31/(1-(1+Inputs!$C$31)^-30)*K4 -> 127851.38 | ... AG33: =NPV(Inputs!$C$31,$D$9:$AG$9)*Inputs!$C$31/(1-(1+Inputs!$C$31)^-30)*AG4 -> 197655.63
A34: CFADS | C34: 0 | D34: =D11-D30-D33-D32 -> 1088726 | E34: =E11-E30-E33-E32 -> 1872784.5 | F34: =F11-F30-F33-F32 -> 1910240.2 | G34: =G11-G30-G33-G32 -> 1948445 | H34: =H11-H30-H33-H32 -> 1987413.9 | I34: =I11-I30-I33-I32 -> 1943525.3 | J34: =J11-J30-J33-J32 -> 1618722.1 | K34: =K11-K30-K33-K32 -> 1635626.8 | ... AG34: =AG11-AG30-AG33-AG32 -> 2658013.4
A35: DSCR | D35: =IF(D26>0,D34/D26,"") -> 2.1251214 | E35: =IF(E26>0,E34/E26,"") -> 1.6524313 | F35: =IF(F26>0,F34/F26,"") -> 1.7149608 | G35: =IF(G26>0,G34/G26,"") -> 1.7804011 | H35: =IF(H26>0,H34/H26,"") -> 1.8489246 | I35: =IF(I26>0,I34/I26,"") -> 1.8414712 | J35: =IF(J26>0,J34/J26,"") -> 1.5625679 | K35: =IF(K26>0,K34/K26,"") -> 1.6091493 | ... AG35: =IF(AG26>0,AG34/AG26,"")
A36: DSRA balance | C36: =Inputs!$C$30/12*MAX(D26,E26) -> 566675.48 | D36: =Inputs!$C$30/12*E26 -> 566675.48 | E36: =Inputs!$C$30/12*F26 -> 556934.1 | F36: =Inputs!$C$30/12*G26 -> 547192.71 | G36: =Inputs!$C$30/12*H26 -> 537451.33 | H36: =Inputs!$C$30/12*I26 -> 527709.95 | I36: =Inputs!$C$30/12*J26 -> 517968.57 | J36: =Inputs!$C$30/12*K26 -> 508227.19 | K36: =Inputs!$C$30/12*L26 -> 498485.8 | ... AF36: =Inputs!$C$30/12*AG26 -> 0 | AG36: 0
A37: DSRA build | C37: =C36-0 -> 566675.48 | D37: =D36-C36 -> 0 | E37: =E36-D36 -> -9741.3819 | F37: =F36-E36 -> -9741.3819 | G37: =G36-F36 -> -9741.3819 | H37: =H36-G36 -> -9741.3819 | I37: =I36-H36 -> -9741.3819 | J37: =J36-I36 -> -9741.3819 | K37: =K36-J36 -> -9741.3819 | ... AG37: =AG36-AF36 -> 0
A38: Cash flow to equity | C38: =-(SUM(Inputs!$C$36:$C$52)*Inputs!$C$11-C20-C23-Inputs!$C$26)-C32-C37-C20*Inputs!$C$20-C23*Inputs!$C$25 -> -4343008.2 | D38: =D11-D13-D30-D26-D32-D37+D14 -> 687715.93 | E38: =E11-E13-E30-E26-E32-E37+E14 -> 862703.34 | F38: =F11-F13-F30-F26-F32-F37+F14 -> 921912.36 | G38: =G11-G13-G30-G26-G32-G37+G14 -> 981915.91 | H38: =H11-H13-H30-H26-H32-H37+H14 -> 1042729.9 | I38: =I11-I13-I30-I26-I32-I37+I14 -> 1020733.5 | J38: =J11-J13-J30-J26-J32-J37+J14 -> 717870.87 | K38: =K11-K13-K30-K26-K32-K37+K14 -> 756765.19 | ... AG38: =AG11-AG13-AG30-AG26-AG32-AG37+AG14 -> 6619563.8
A39: Cumulative equity cash | C39: =0+C38 -> -4343008.2 | D39: =C39+D38 -> -3655292.2 | E39: =D39+E38 -> -2792588.9 | F39: =E39+F38 -> -1870676.5 | G39: =F39+G38 -> -888760.63 | H39: =G39+H38 -> 153969.24 | I39: =H39+I38 -> 1174702.8 | J39: =I39+J38 -> 1892573.6 | K39: =J39+K38 -> 2649338.8 | ... AG39: =AF39+AG38 -> 44502687
