Workbook

Sheet Results
A1: Plan finance model (8 ha): results
A2: Senior debt sized to DSCR 1.25 on the yield -15 % case (bplan_plan.LenderSizing), year-1 interest rolled up, full team in opex. Change blue cells on Inputs; the service schedule row is the sizing at the default inputs.
A4: Output | B4: Workbook | C4: finance.py (default inputs)
A5: Capex (GBP) | B5: =SUM(Inputs!$C$30:$C$46)*Inputs!$C$11 -> 28656012 | C5: 28656012
A6: Debt drawn (GBP) | B6: =Cashflow!C20 -> 19649527 | C6: 19649527
A7: Equity at close (GBP) | B7: =-Cashflow!C35 -> 11426286 | C7: 11426286
A8: Project IRR, real pre-tax | B8: =IRR(Cashflow!C10:AG10) -> 0.13525 | C8: 0.13525
A9: Equity IRR, nominal post-tax | B9: =IRR(Cashflow!C35:AG35) -> 0.20140623 | C9: 0.20140623
A10: Equity IRR, real | B10: =(1+B9)/(1+Inputs!$C$6)-1 -> 0.17784925 | C10: 0.17784925
A11: DSCR year 1 | B11: =Cashflow!D32
A12: Minimum DSCR | B12: =MIN(Cashflow!D32:AG32) -> 1.5199975 | C12: 1.5199975
A13: Tax paid over 30 yr (GBP) | B13: =SUM(Cashflow!C27:AG27) -> 32906178 | C13: 32906178
A14: Equity NPV at the hurdle (GBP) | B14: =NPV(Inputs!$C$22,Cashflow!D35:AG35)+Cashflow!C35 -> 8578720.9 | C14: 8578720.9
A15: Lender test met (min DSCR >= target) | B15: =IF(B12>=Inputs!$C$21,"yes","NO") -> yes
A17: Price for a 12 % nominal equity return with the debt re-sized at each price (bplan_plan.LenderSizing).
A18: Minimum price (GBP/kg) | C18: 1.3400297

Sheet Inputs
A1: Lead finance model: inputs (blue = input)
A2: Lit lead 8.0 ha, 150 umol, 4 PPA turbines, Stranraer; physics from lit_open.json; terms and tiers in finance.py
A4: Contract price, real (year-0 GBP/kg) | C4: 1.4742433 | D4: default = import parity 1.552 x 0.90; CPI-indexed
A5: Import parity (GBP/kg) | C5: 1.551835 | D5: monthly CIF + GBP 0.162 haul, weighted by own harvest
A6: CPI | C6: 0.02 | D6: Bank of England target
A7: Corporation tax | C7: 0.25 | D7: main rate
A8: Output at full yield (kg/yr) | C8: 7131687.2 | D8: model, before stresses
A9: Year-1 output share | C9: 0.8 | D9: first-crop establishment
A10: Stress: yield x | C10: 1
A11: Stress: capex x (incl. replacements) | C11: 1
A12: Stress: power cost x | C12: 1
A13: CO2 price (GBP/kg) | C13: 0.06 | D13: by-product CO2 (PLACEHOLDER); model base 0.06
A14: Stress: labour x | C14: 1
A15: Share of labour that scales with kg | C15: 0.5 | D15: PLACEHOLDER
A16: Senior debt drawn at close (GBP) | C16: 19649527 | D16: sized to DSCR 1.25 on the yield -15 % case
A17: Senior debt rate | C17: 0.065 | D17: blend of GBP CIRR 5.81 % and bank 6.75 %, PLACEHOLDER
A18: Senior debt tenor (yr) | C18: 15 | D18: year-1 interest rolled into the loan
A19: Lender fees, up front | C19: 0.015 | D19: PLACEHOLDER
A20: Capital grant (GBP) | C20: 0 | D20: FDPSS up to GBP 0.4 M, packhouse only (GRANTS.md)
A21: Lender minimum DSCR | C21: 1.25 | D21: PLACEHOLDER 1.20-1.35
A22: Equity hurdle, nominal post-tax | C22: 0.12 | D22: PLACEHOLDER
A23: Working capital (months of opex) | C23: 2
A24: DSRA (months of next year's debt service) | C24: 6
A25: Maintenance-reserve rate (real) | C25: 0.06 | D25: levels the lumpy replacements for CFADS
A26: Special-rate first-year allowance | C26: 0.5 | D26: CAA 2001 s.45S
A27: Special-rate writing-down allowance | C27: 0.06
A29: Capex lines (GBP, year 0) | C29: GBP | D29: Finance / allowance class
A30: steel | B30: ECA | C30: 2036081.7 | D30: main
A31: aluminium | B31: ECA | C31: 508761.67 | D31: main
A32: glass_single_m2 | B32: ECA | C32: 2208167 | D32: main
A33: concrete | B33: ECA | C33: 157299.54 | D33: main
A34: pir_panel_m2 | B34: ECA | C34: 0 | D34: main
A35: heating_pipe_m | B35: ECA | C35: 2880000 | D35: special
A36: energy_screen_m2 | B36: ECA | C36: 480000 | D36: main
A37: residual (SAC-calibrated: install, climate computer, irrigation, vents ...) | B37: ECA | C37: 6382108.7 | D37: main
A38: heat_pump | B38: AF | C38: 5983326.1 | D38: special
A39: peak_boiler | B39: AF | C39: 0 | D39: special
A40: hot_water_store | B40: AF | C40: 1138627.1 | D40: special
A41: battery | B41: AF | C41: 0 | D41: special
... A46: contingency | B46: - | C46: 2491827.2 | D46: contingency
...

Sheet Cashflow
A1: Plan finance model (8 ha): annual cash flow (nominal GBP unless marked real)
C3: 0 | D3: 1 | E3: 2 | F3: 3 | G3: 4 | H3: 5 | I3: 6 | J3: 7 | K3: 8 | L3: 9 | M3: 10 | N3: 11 | O3: 12 | P3: 13 | Q3: 14 | R3: 15 | S3: 16 | T3: 17 | U3: 18 | V3: 19 | W3: 20 | X3: 21 | Y3: 22 | Z3: 23 | AA3: 24 | AB3: 25 | AC3: 26 | AD3: 27 | AE3: 28 | AF3: 29 | AG3: 30
A4: CPI index | C4: =(1+Inputs!$C$6)^C3 -> 1 | D4: =(1+Inputs!$C$6)^D3 -> 1.02 | E4: =(1+Inputs!$C$6)^E3 -> 1.0404 | F4: =(1+Inputs!$C$6)^F3 -> 1.061208 | G4: =(1+Inputs!$C$6)^G3 -> 1.0824322 | H4: =(1+Inputs!$C$6)^H3 -> 1.1040808 | I4: =(1+Inputs!$C$6)^I3 -> 1.1261624 | J4: =(1+Inputs!$C$6)^J3 -> 1.1486857 | ... AG4: =(1+Inputs!$C$6)^AG3 -> 1.8113616
A5: Output share | C5: 0 | D5: =Inputs!$C$9 -> 0.8 | E5: 1 | F5: 1 | G5: 1 | H5: 1 | I5: 1 | J5: 1 | K5: 1 | L5: 1 | M5: 1 | N5: 1 | O5: 1 | P5: 1 | Q5: 1 | R5: 1 | S5: 1 | T5: 1 | U5: 1 | V5: 1 | W5: 1 | X5: 1 | Y5: 1 | Z5: 1 | AA5: 1 | AB5: 1 | AC5: 1 | AD5: 1 | AE5: 1 | AF5: 1 | AG5: 1
A6: kg sold | C6: =Inputs!$C$8*Inputs!$C$10*C5 -> 0 | D6: =Inputs!$C$8*Inputs!$C$10*D5 -> 5705349.7 | E6: =Inputs!$C$8*Inputs!$C$10*E5 -> 7131687.2 | F6: =Inputs!$C$8*Inputs!$C$10*F5 -> 7131687.2 | G6: =Inputs!$C$8*Inputs!$C$10*G5 -> 7131687.2 | H6: =Inputs!$C$8*Inputs!$C$10*H5 -> 7131687.2 | I6: =Inputs!$C$8*Inputs!$C$10*I5 -> 7131687.2 | J6: =Inputs!$C$8*Inputs!$C$10*J5 -> 7131687.2 | ... AG6: =Inputs!$C$8*Inputs!$C$10*AG5 -> 7131687.2
A7: Revenue, real | C7: =Inputs!$C$4*C6 -> 0 | D7: =Inputs!$C$4*D6 -> 8411073.4 | E7: =Inputs!$C$4*E6 -> 10513842 | F7: =Inputs!$C$4*F6 -> 10513842 | G7: =Inputs!$C$4*G6 -> 10513842 | H7: =Inputs!$C$4*H6 -> 10513842 | I7: =Inputs!$C$4*I6 -> 10513842 | J7: =Inputs!$C$4*J6 -> 10513842 | ... AG7: =Inputs!$C$4*AG6 -> 10513842
A8: Opex, real | C8: 0 | D8: =SUMIF(Inputs!$D$49:$D$67,"fixed",Inputs!$C$49:$C$67)+SUMIF(Inputs!$D$49:$D$67,"labour",Inputs!$C$49:$C$67)*Inputs!$C$14*((1-Inputs!$C$15)+Inputs!$C$15*Inputs!$C$10)+SUMIF(Inputs!$D$49:$D$67,"elec",Inputs!$C$49:$C$67)*Inputs!$C$12+SUMIF(Inputs!$D$49:$D$67,"co2_purchased",Inputs!$C$49:$C$67)*Inputs!$C$13/0.06+SUMIF(Inputs!$D$49:$D$67,"per_kg",Inputs!$C$49:$C$67)/Inputs!$C$8*D6+SUMIF(Inputs!$D$49:$D$67,"sales_commission",Inputs!$C$49:$C$67)/Inputs!$C$70*D7 -> 6085018.6 | E8: =SUMIF(Inputs!$D$49:$D$67,"fixed",Inputs!$C$49:$C$67)+SUMIF(Inputs!$D$49:$D$67,"labour",Inputs!$C$49:$C$67)*Inputs!$C$14*((1-Inputs!$C$15)+Inputs!$C$15*Inputs!$C$10)+SUMIF(Inputs!$D$49:$D$67,"elec",Inputs!$C$49:$C$67)*Inputs!$C$12+SUMIF(Inputs!$D$49:$D$67,"co2_purchased",Inputs!$C$49:$C$67)*Inputs!$C$13/0.06+SUMIF(Inputs!$D$49:$D$67,"per_kg",Inputs!$C$49:$C$67)/Inputs!$C$8*E6+SUMIF(Inputs!$D$49:$D$67,"sales_commission",Inputs!$C$49:$C$67)/Inputs!$C$70*E7 -> 6156335.5 | F8: =SUMIF(Inputs!$D$49:$D$67,"fixed",Inputs!$C$49:$C$67)+SUMIF(Inputs!$D$49:$D$67,"labour",Inputs!$C$49:$C$67)*Inputs!$C$14*((1-Inputs!$C$15)+Inputs!$C$15*Inputs!$C$10)+SUMIF(Inputs!$D$49:$D$67,"elec",Inputs!$C$49:$C$67)*Inputs!$C$12+SUMIF(Inputs!$D$49:$D$67,"co2_purchased",Inputs!$C$49:$C$67)*Inputs!$C$13/0.06+SUMIF(Inputs!$D$49:$D$67,"per_kg",Inputs!$C$49:$C$67)/Inputs!$C$8*F6+SUMIF(Inputs!$D$49:$D$67,"sales_commission",Inputs!$C$49:$C$67)/Inputs!$C$70*F7 -> 6156335.5 | G8: =SUMIF(Inputs!$D$49:$D$67,"fixed",Inputs!$C$49:$C$67)+SUMIF(Inputs!$D$49:$D$67,"labour",Inputs!$C$49:$C$67)*Inputs!$C$14*((1-Inputs!$C$15)+Inputs!$C$15*Inputs!$C$10)+SUMIF(Inputs!$D$49:$D$67,"elec",Inputs!$C$49:$C$67)*Inputs!$C$12+SUMIF(Inputs!$D$49:$D$67,"co2_purchased",Inputs!$C$49:$C$67)*Inputs!$C$13/0.06+SUMIF(Inputs!$D$49:$D$67,"per_kg",Inputs!$C$49:$C$67)/Inputs!$C$8*G6+SUMIF(Inputs!$D$49:$D$67,"sales_commission",Inputs!$C$49:$C$67)/Inputs!$C$70*G7 -> 6156335.5 | H8: =SUMIF(Inputs!$D$49:$D$67,"fixed",Inputs!$C$49:$C$67)+SUMIF(Inputs!$D$49:$D$67,"labour",Inputs!$C$49:$C$67)*Inputs!$C$14*((1-Inputs!$C$15)+Inputs!$C$15*Inputs!$C$10)+SUMIF(Inputs!$D$49:$D$67,"elec",Inputs!$C$49:$C$67)*Inputs!$C$12+SUMIF(Inputs!$D$49:$D$67,"co2_purchased",Inputs!$C$49:$C$67)*Inputs!$C$13/0.06+SUMIF(Inputs!$D$49:$D$67,"per_kg",Inputs!$C$49:$C$67)/Inputs!$C$8*H6+SUMIF(Inputs!$D$49:$D$67,"sales_commission",Inputs!$C$49:$C$67)/Inputs!$C$70*H7 -> 6156335.5 | I8: =SUMIF(Inputs!$D$49:$D$67,"fixed",Inputs!$C$49:$C$67)+SUMIF(Inputs!$D$49:$D$67,"labour",Inputs!$C$49:$C$67)*Inputs!$C$14*((1-Inputs!$C$15)+Inputs!$C$15*Inputs!$C$10)+SUMIF(Inputs!$D$49:$D$67,"elec",Inputs!$C$49:$C$67)*Inputs!$C$12+SUMIF(Inputs!$D$49:$D$67,"co2_purchased",Inputs!$C$49:$C$67)*Inputs!$C$13/0.06+SUMIF(Inputs!$D$49:$D$67,"per_kg",Inputs!$C$49:$C$67)/Inputs!$C$8*I6+SUMIF(Inputs!$D$49:$D$67,"sales_commission",Inputs!$C$49:$C$67)/Inputs!$C$70*I7 -> 6156335.5 | J8: =SUMIF(Inputs!$D$49:$D$67,"fixed",Inputs!$C$49:$C$67)+SUMIF(Inputs!$D$49:$D$67,"labour",Inputs!$C$49:$C$67)*Inputs!$C$14*((1-Inputs!$C$15)+Inputs!$C$15*Inputs!$C$10)+SUMIF(Inputs!$D$49:$D$67,"elec",Inputs!$C$49:$C$67)*Inputs!$C$12+SUMIF(Inputs!$D$49:$D$67,"co2_purchased",Inputs!$C$49:$C$67)*Inputs!$C$13/0.06+SUMIF(Inputs!$D$49:$D$67,"per_kg",Inputs!$C$49:$C$67)/Inputs!$C$8*J6+SUMIF(Inputs!$D$49:$D$67,"sales_commission",Inputs!$C$49:$C$67)/Inputs!$C$70*J7 -> 6156335.5 | K8: =SUMIF(Inputs!$D$49:$D$67,"fixed",Inputs!$C$49:$C$67)+SUMIF(Inputs!$D$49:$D$67,"labour",Inputs!$C$49:$C$67)*Inputs!$C$14*((1-Inputs!$C$15)+Inputs!$C$15*Inputs!$C$10)+SUMIF(Inputs!$D$49:$D$67,"elec",Inputs!$C$49:$C$67)*Inputs!$C$12+SUMIF(Inputs!$D$49:$D$67,"co2_purchased",Inputs!$C$49:$C$67)*Inputs!$C$13/0.06+SUMIF(Inputs!$D$49:$D$67,"per_kg",Inputs!$C$49:$C$67)/Inputs!$C$8*K6+SUMIF(Inputs!$D$49:$D$67,"sales_commission",Inputs!$C$49:$C$67)/Inputs!$C$70*K7 -> 6156335.5 | ... AG8: =SUMIF(Inputs!$D$49:$D$67,"fixed",Inputs!$C$49:$C$67)+SUMIF(Inputs!$D$49:$D$67,"labour",Inputs!$C$49:$C$67)*Inputs!$C$14*((1-Inputs!$C$15)+Inputs!$C$15*Inputs!$C$10)+SUMIF(Inputs!$D$49:$D$67,"elec",Inputs!$C$49:$C$67)*Inputs!$C$12+SUMIF(Inputs!$D$49:$D$67,"co2_purchased",Inputs!$C$49:$C$67)*Inputs!$C$13/0.06+SUMIF(Inputs!$D$49:$D$67,"per_kg",Inputs!$C$49:$C$67)/Inputs!$C$8*AG6+SUMIF(Inputs!$D$49:$D$67,"sales_commission",Inputs!$C$49:$C$67)/Inputs!$C$70*AG7 -> 6156335.5
A9: Replacement capex, real | C9: =Inputs!E74*Inputs!$C$11 -> 0 | D9: =Inputs!F74*Inputs!$C$11 -> 0 | E9: =Inputs!G74*Inputs!$C$11 -> 0 | F9: =Inputs!H74*Inputs!$C$11 -> 0 | G9: =Inputs!I74*Inputs!$C$11 -> 0 | H9: =Inputs!J74*Inputs!$C$11 -> 0 | I9: =Inputs!K74*Inputs!$C$11 -> 0 | J9: =Inputs!L74*Inputs!$C$11 -> 0 | ... AG9: =Inputs!AI74*Inputs!$C$11 -> 0
A10: Unlevered cash flow, real pre-tax | C10: =-SUM(Inputs!$C$30:$C$46)*Inputs!$C$11 -> -28656012 | D10: =D7-D8-D9 -> 2326054.8 | E10: =E7-E8-E9 -> 4357506.3 | F10: =F7-F8-F9 -> 4357506.3 | G10: =G7-G8-G9 -> 4357506.3 | H10: =H7-H8-H9 -> 4357506.3 | I10: =I7-I8-I9 -> 4357506.3 | J10: =J7-J8-J9 -> 4357506.3 | K10: =K7-K8-K9 -> 4357506.3 | ... AF10: =AF7-AF8-AF9 -> 4357506.3 | AG10: =AG7-AG8-AG9+Inputs!$C$69*Inputs!$C$11 -> 9676009.6
A11: EBITDA, nominal | C11: =(C7-C8)*C4 -> 0 | D11: =(D7-D8)*D4 -> 2372575.9 | E11: =(E7-E8)*E4 -> 4533549.6 | F11: =(F7-F8)*F4 -> 4624220.6 | G11: =(G7-G8)*G4 -> 4716705 | H11: =(H7-H8)*H4 -> 4811039.1 | I11: =(I7-I8)*I4 -> 4907259.9 | J11: =(J7-J8)*J4 -> 5005405.1 | ... AG11: =(AG7-AG8)*AG4 -> 7893019.6
A12: Opex, nominal | C12: =C8*C4 -> 0 | D12: =D8*D4 -> 6206719 | E12: =E8*E4 -> 6405051.4 | F12: =F8*F4 -> 6533152.4 | G12: =G8*G4 -> 6663815.5 | H12: =H8*H4 -> 6797091.8 | I12: =I8*I4 -> 6933033.6 | J12: =J8*J4 -> 7071694.3 | ... AG12: =AG8*AG4 -> 11151350
A13: Replacements, nominal | C13: =C9*C4 -> 0 | D13: =D9*D4 -> 0 | E13: =E9*E4 -> 0 | F13: =F9*F4 -> 0 | G13: =G9*G4 -> 0 | H13: =H9*H4 -> 0 | I13: =I9*I4 -> 0 | J13: =J9*J4 -> 0 | ... AG13: =AG9*AG4 -> 0
A14: Residual value, nominal | C14: 0 | D14: 0 | E14: 0 | F14: 0 | G14: 0 | H14: 0 | I14: 0 | J14: 0 | K14: 0 | L14: 0 | M14: 0 | N14: 0 | O14: 0 | P14: 0 | Q14: 0 | R14: 0 | S14: 0 | T14: 0 | U14: 0 | V14: 0 | W14: 0 | X14: 0 | Y14: 0 | Z14: 0 | AA14: 0 | AB14: 0 | AC14: 0 | AD14: 0 | AE14: 0 | AF14: 0 | AG14: =Inputs!$C$69*Inputs!$C$11*AG4 -> 9633732.5
A15: Special-rate pool additions | C15: =SUMIF(Inputs!$D$30:$D$46,"special",Inputs!$C$30:$C$46)*Inputs!$C$11*(1+SUMIF(Inputs!$D$30:$D$46,"contingency",Inputs!$C$30:$C$46)*Inputs!$C$11/(SUMIF(Inputs!$D$30:$D$46,"main",Inputs!$C$30:$C$46)*Inputs!$C$11+SUMIF(Inputs!$D$30:$D$46,"special",Inputs!$C$30:$C$46)*Inputs!$C$11))*(1-Inputs!$C$20/(SUMIF(Inputs!$D$30:$D$46,"main",Inputs!$C$30:$C$46)*Inputs!$C$11+SUMIF(Inputs!$D$30:$D$46,"special",Inputs!$C$30:$C$46)*Inputs!$C$11+SUMIF(Inputs!$D$30:$D$46,"contingency",Inputs!$C$30:$C$46)*Inputs!$C$11)) -> 13323002 | D15: =D13 -> 0 | E15: =E13 -> 0 | F15: =F13 -> 0 | G15: =G13 -> 0 | H15: =H13 -> 0 | I15: =I13 -> 0 | J15: =J13 -> 0 | K15: =K13 -> 0 | ... AG15: =AG13 -> 0
A16: First-year allowance (special) | C16: =Inputs!$C$26*C15 -> 6661500.9 | D16: =Inputs!$C$26*D15 -> 0 | E16: =Inputs!$C$26*E15 -> 0 | F16: =Inputs!$C$26*F15 -> 0 | G16: =Inputs!$C$26*G15 -> 0 | H16: =Inputs!$C$26*H15 -> 0 | I16: =Inputs!$C$26*I15 -> 0 | J16: =Inputs!$C$26*J15 -> 0 | ... AG16: =Inputs!$C$26*AG15 -> 0
A17: Writing-down allowance (special) | C17: =Inputs!$C$27*(0+C15-C16) -> 399690.06 | D17: =Inputs!$C$27*(C18+D15-D16) -> 375708.65 | E17: =Inputs!$C$27*(D18+E15-E16) -> 353166.13 | F17: =Inputs!$C$27*(E18+F15-F16) -> 331976.16 | G17: =Inputs!$C$27*(F18+G15-G16) -> 312057.59 | H17: =Inputs!$C$27*(G18+H15-H16) -> 293334.14 | I17: =Inputs!$C$27*(H18+I15-I16) -> 275734.09 | J17: =Inputs!$C$27*(I18+J15-J16) -> 259190.05 | K17: =Inputs!$C$27*(J18+K15-K16) -> 243638.64 | ... AG17: =Inputs!$C$27*(AF18+AG15-AG16) -> 389093.66
A18: Special-rate pool, closing | C18: =0+C15-C16-C17 -> 6261810.9 | D18: =C18+D15-D16-D17 -> 5886102.2 | E18: =D18+E15-E16-E17 -> 5532936.1 | F18: =E18+F15-F16-F17 -> 5200959.9 | G18: =F18+G15-G16-G17 -> 4888902.3 | H18: =G18+H15-H16-H17 -> 4595568.2 | I18: =H18+I15-I16-I17 -> 4319834.1 | J18: =I18+J15-J16-J17 -> 4060644 | K18: =J18+K15-K16-K17 -> 3817005.4 | ... AG18: =AF18+AG15-AG16-AG17 -> 6095800.7
A19: Capital allowances | C19: =(SUMIF(Inputs!$D$30:$D$46,"main",Inputs!$C$30:$C$46)*Inputs!$C$11+SUMIF(Inputs!$D$30:$D$46,"special",Inputs!$C$30:$C$46)*Inputs!$C$11+SUMIF(Inputs!$D$30:$D$46,"contingency",Inputs!$C$30:$C$46)*Inputs!$C$11)*(1-Inputs!$C$20/(SUMIF(Inputs!$D$30:$D$46,"main",Inputs!$C$30:$C$46)*Inputs!$C$11+SUMIF(Inputs!$D$30:$D$46,"special",Inputs!$C$30:$C$46)*Inputs!$C$11+SUMIF(Inputs!$D$30:$D$46,"contingency",Inputs!$C$30:$C$46)*Inputs!$C$11))-C15+C16+C17 -> 20064388 | D19: =D16+D17 -> 375708.65 | E19: =E16+E17 -> 353166.13 | F19: =F16+F17 -> 331976.16 | G19: =G16+G17 -> 312057.59 | H19: =H16+H17 -> 293334.14 | I19: =I16+I17 -> 275734.09 | J19: =J16+J17 -> 259190.05 | K19: =K16+K17 -> 243638.64 | ... AF19: =AF16+AF17 -> 413929.43 | AG19: =AG16+AG17+AG18-AG14 -> -3148838.2
A20: Senior debt, closing balance | B20: =C20 -> 19649527 | C20: =Inputs!$C$16 -> 19649527 | D20: =C20*(1+Inputs!$C$17) -> 20926747 | E20: =D20-E22 -> 20105776 | F20: =E20-F22 -> 19187818 | G20: =F20-G22 -> 18165697 | H20: =G20-H22 -> 17031751 | I20: =H20-I22 -> 15777804 | J20: =I20-J22 -> 14395130 | K20: =J20-K22 -> 12874418 | L20: =K20-L22 -> 11205731 | ... AG20: =AF20-AG22 -> 0
A21: Senior debt interest (year 1 rolled up) | C21: 0 | D21: 0 | E21: =IF(2<=Inputs!$C$18,D20*Inputs!$C$17,0) -> 1360238.5 | F21: =IF(3<=Inputs!$C$18,E20*Inputs!$C$17,0) -> 1306875.4 | G21: =IF(4<=Inputs!$C$18,F20*Inputs!$C$17,0) -> 1247208.2 | H21: =IF(5<=Inputs!$C$18,G20*Inputs!$C$17,0) -> 1180770.3 | I21: =IF(6<=Inputs!$C$18,H20*Inputs!$C$17,0) -> 1107063.8 | J21: =IF(7<=Inputs!$C$18,I20*Inputs!$C$17,0) -> 1025557.2 | K21: =IF(8<=Inputs!$C$18,J20*Inputs!$C$17,0) -> 935683.44 | L21: =IF(9<=Inputs!$C$18,K20*Inputs!$C$17,0) -> 836837.15 | M21: =IF(10<=Inputs!$C$18,L20*Inputs!$C$17,0) -> 728372.54 | N21: =IF(11<=Inputs!$C$18,M20*Inputs!$C$17,0) -> 609600.54 | O21: =IF(12<=Inputs!$C$18,N20*Inputs!$C$17,0) -> 482498.99 | P21: =IF(13<=Inputs!$C$18,O20*Inputs!$C$17,0) -> 379988.41 | Q21: =IF(14<=Inputs!$C$18,P20*Inputs!$C$17,0) -> 269834.26 | R21: =IF(15<=Inputs!$C$18,Q20*Inputs!$C$17,0) -> 151578.46 | S21: =IF(16<=Inputs!$C$18,R20*Inputs!$C$17,0) -> 0 | T21: =IF(17<=Inputs!$C$18,S20*Inputs!$C$17,0) -> 0 | U21: =IF(18<=Inputs!$C$18,T20*Inputs!$C$17,0) -> 0 | V21: =IF(19<=Inputs!$C$18,U20*Inputs!$C$17,0) -> 0 | W21: =IF(20<=Inputs!$C$18,V20*Inputs!$C$17,0) -> 0 | X21: =IF(21<=Inputs!$C$18,W20*Inputs!$C$17,0) -> 0 | Y21: =IF(22<=Inputs!$C$18,X20*Inputs!$C$17,0) -> 0 | Z21: =IF(23<=Inputs!$C$18,Y20*Inputs!$C$17,0) -> 0 | AA21: =IF(24<=Inputs!$C$18,Z20*Inputs!$C$17,0) -> 0 | AB21: =IF(25<=Inputs!$C$18,AA20*Inputs!$C$17,0) -> 0 | AC21: =IF(26<=Inputs!$C$18,AB20*Inputs!$C$17,0) -> 0 | AD21: =IF(27<=Inputs!$C$18,AC20*Inputs!$C$17,0) -> 0 | AE21: =IF(28<=Inputs!$C$18,AD20*Inputs!$C$17,0) -> 0 | AF21: =IF(29<=Inputs!$C$18,AE20*Inputs!$C$17,0) -> 0 | AG21: =IF(30<=Inputs!$C$18,AF20*Inputs!$C$17,0) -> 0
A22: Senior debt principal (service schedule less interest) | C22: 0 | D22: 0 | E22: =MAX(MIN(Inputs!G77-E21,D20),0) -> 820970.47 | F22: =MAX(MIN(Inputs!H77-F21,E20),0) -> 917957.73 | G22: =MAX(MIN(Inputs!I77-G21,F20),0) -> 1022121.6 | H22: =MAX(MIN(Inputs!J77-H21,G20),0) -> 1133946.1 | I22: =MAX(MIN(Inputs!K77-I21,H20),0) -> 1253947 | J22: =MAX(MIN(Inputs!L77-J21,I20),0) -> 1382673.7 | K22: =MAX(MIN(Inputs!M77-K21,J20),0) -> 1520712.2 | L22: =MAX(MIN(Inputs!N77-L21,K20),0) -> 1668686.4 | ... AG22: =MAX(MIN(Inputs!AI77-AG21,AF20),0) -> 0
A23: Debt service | C23: =C21+C22 -> 0 | D23: =D21+D22 -> 0 | E23: =E21+E22 -> 2181209 | F23: =F21+F22 -> 2224833.2 | G23: =G21+G22 -> 2269329.8 | H23: =H21+H22 -> 2314716.4 | I23: =I21+I22 -> 2361010.8 | J23: =J21+J22 -> 2408231 | ... AG23: =AG21+AG22 -> 0
A24: Taxable profit before losses | C24: =C11-C19-C21 -> -20064388 | D24: =D11-D19-D21 -> 1996867.3 | E24: =E11-E19-E21 -> 2820144.9 | F24: =F11-F19-F21 -> 2985369 | G24: =G11-G19-G21 -> 3157439.2 | H24: =H11-H19-H21 -> 3336934.7 | I24: =I11-I19-I21 -> 3524462 | J24: =J11-J19-J21 -> 3720657.8 | ... AG24: =AG11-AG19-AG21 -> 11041858
A25: Losses used | C25: 0 | D25: =MIN(C26,MAX(D24,0)) -> 1996867.3 | E25: =MIN(D26,MAX(E24,0)) -> 2820144.9 | F25: =MIN(E26,MAX(F24,0)) -> 2985369 | G25: =MIN(F26,MAX(G24,0)) -> 3157439.2 | H25: =MIN(G26,MAX(H24,0)) -> 3336934.7 | I25: =MIN(H26,MAX(I24,0)) -> 3524462 | J25: =MIN(I26,MAX(J24,0)) -> 2243170.9 | K25: =MIN(J26,MAX(K24,0)) -> 0 | ... AG25: =MIN(AF26,MAX(AG24,0)) -> 0
A26: Losses carried forward | C26: =0-C25+MAX(-C24,0) -> 20064388 | D26: =C26-D25+MAX(-D24,0) -> 18067521 | E26: =D26-E25+MAX(-E24,0) -> 15247376 | F26: =E26-F25+MAX(-F24,0) -> 12262007 | G26: =F26-G25+MAX(-G24,0) -> 9104567.6 | H26: =G26-H25+MAX(-H24,0) -> 5767632.9 | I26: =H26-I25+MAX(-I24,0) -> 2243170.9 | J26: =I26-J25+MAX(-J24,0) -> 0 | K26: =J26-K25+MAX(-K24,0) -> 0 | ... AG26: =AF26-AG25+MAX(-AG24,0) -> 0
A27: Corporation tax paid | C27: =Inputs!$C$7*(MAX(C24,0)-C25) -> 0 | D27: =Inputs!$C$7*(MAX(D24,0)-D25) -> 0 | E27: =Inputs!$C$7*(MAX(E24,0)-E25) -> 0 | F27: =Inputs!$C$7*(MAX(F24,0)-F25) -> 0 | G27: =Inputs!$C$7*(MAX(G24,0)-G25) -> 0 | H27: =Inputs!$C$7*(MAX(H24,0)-H25) -> 0 | I27: =Inputs!$C$7*(MAX(I24,0)-I25) -> 0 | J27: =Inputs!$C$7*(MAX(J24,0)-J25) -> 369371.72 | ... AG27: =Inputs!$C$7*(MAX(AG24,0)-AG25) -> 2760464.4
A28: Working capital balance | C28: =Inputs!$C$23/12*D12 -> 1034453.2 | D28: =Inputs!$C$23/12*E12 -> 1067508.6 | E28: =Inputs!$C$23/12*F12 -> 1088858.7 | F28: =Inputs!$C$23/12*G12 -> 1110635.9 | G28: =Inputs!$C$23/12*H12 -> 1132848.6 | H28: =Inputs!$C$23/12*I12 -> 1155505.6 | I28: =Inputs!$C$23/12*J12 -> 1178615.7 | J28: =Inputs!$C$23/12*K12 -> 1202188 | ... AF28: =Inputs!$C$23/12*AG12 -> 1858558.3 | AG28: 0
A29: Working-capital build | C29: =C28-0 -> 1034453.2 | D29: =D28-C28 -> 33055.409 | E29: =E28-D28 -> 21350.171 | F29: =F28-E28 -> 21777.175 | G29: =G28-F28 -> 22212.718 | H29: =H28-G28 -> 22656.973 | I29: =I28-H28 -> 23110.112 | J29: =J28-I28 -> 23572.314 | K29: =K28-J28 -> 24043.761 | ... AG29: =AG28-AF28 -> -1858558.3
A30: Maintenance reserve | C30: 0 | D30: =NPV(Inputs!$C$25,$D$9:$AG$9)*Inputs!$C$25/(1-(1+Inputs!$C$25)^-30)*D4 -> 289337.13 | E30: =NPV(Inputs!$C$25,$D$9:$AG$9)*Inputs!$C$25/(1-(1+Inputs!$C$25)^-30)*E4 -> 295123.88 | F30: =NPV(Inputs!$C$25,$D$9:$AG$9)*Inputs!$C$25/(1-(1+Inputs!$C$25)^-30)*F4 -> 301026.35 | G30: =NPV(Inputs!$C$25,$D$9:$AG$9)*Inputs!$C$25/(1-(1+Inputs!$C$25)^-30)*G4 -> 307046.88 | H30: =NPV(Inputs!$C$25,$D$9:$AG$9)*Inputs!$C$25/(1-(1+Inputs!$C$25)^-30)*H4 -> 313187.82 | I30: =NPV(Inputs!$C$25,$D$9:$AG$9)*Inputs!$C$25/(1-(1+Inputs!$C$25)^-30)*I4 -> 319451.58 | J30: =NPV(Inputs!$C$25,$D$9:$AG$9)*Inputs!$C$25/(1-(1+Inputs!$C$25)^-30)*J4 -> 325840.61 | K30: =NPV(Inputs!$C$25,$D$9:$AG$9)*Inputs!$C$25/(1-(1+Inputs!$C$25)^-30)*K4 -> 332357.42 | ... AG30: =NPV(Inputs!$C$25,$D$9:$AG$9)*Inputs!$C$25/(1-(1+Inputs!$C$25)^-30)*AG4 -> 513817.81
A31: CFADS | C31: 0 | D31: =D11-D27-D30-D29 -> 2050183.4 | E31: =E11-E27-E30-E29 -> 4217075.5 | F31: =F11-F27-F30-F29 -> 4301417.1 | G31: =G11-G27-G30-G29 -> 4387445.4 | H31: =H11-H27-H30-H29 -> 4475194.3 | I31: =I11-I27-I30-I29 -> 4564698.2 | J31: =J11-J27-J30-J29 -> 4286620.4 | K31: =K11-K27-K30-K29 -> 3767564.2 | ... AG31: =AG11-AG27-AG30-AG29 -> 6477295.6
A32: DSCR | D32: =IF(D23>0,D31/D23,"") | E32: =IF(E23>0,E31/E23,"") -> 1.9333661 | F32: =IF(F23>0,F31/F23,"") -> 1.9333661 | G32: =IF(G23>0,G31/G23,"") -> 1.9333661 | H32: =IF(H23>0,H31/H23,"") -> 1.9333661 | I32: =IF(I23>0,I31/I23,"") -> 1.9333661 | J32: =IF(J23>0,J31/J23,"") -> 1.7799872 | K32: =IF(K23>0,K31/K23,"") -> 1.5337775 | ... AG32: =IF(AG23>0,AG31/AG23,"")
A33: DSRA balance | C33: =Inputs!$C$24/12*MAX(D23,E23) -> 1090604.5 | D33: =Inputs!$C$24/12*E23 -> 1090604.5 | E33: =Inputs!$C$24/12*F23 -> 1112416.6 | F33: =Inputs!$C$24/12*G23 -> 1134664.9 | G33: =Inputs!$C$24/12*H23 -> 1157358.2 | H33: =Inputs!$C$24/12*I23 -> 1180505.4 | I33: =Inputs!$C$24/12*J23 -> 1204115.5 | J33: =Inputs!$C$24/12*K23 -> 1228197.8 | K33: =Inputs!$C$24/12*L23 -> 1252761.8 | ... AF33: =Inputs!$C$24/12*AG23 -> 0 | AG33: 0
A34: DSRA build | C34: =C33-0 -> 1090604.5 | D34: =D33-C33 -> 0 | E34: =E33-D33 -> 21812.09 | F34: =F33-E33 -> 22248.332 | G34: =G33-F33 -> 22693.298 | H34: =H33-G33 -> 23147.164 | I34: =I33-H33 -> 23610.108 | J34: =J33-I33 -> 24082.31 | K34: =K33-J33 -> 24563.956 | ... AG34: =AG33-AF33 -> 0
A35: Cash flow to equity | C35: =-(SUM(Inputs!$C$30:$C$46)*Inputs!$C$11-C20-Inputs!$C$20)-C29-C34-C20*Inputs!$C$19 -> -11426286 | D35: =D11-D13-D27-D23-D29-D34+D14 -> 2339520.5 | E35: =E11-E13-E27-E23-E29-E34+E14 -> 2309178.3 | F35: =F11-F13-F27-F23-F29-F34+F14 -> 2355361.9 | G35: =G11-G13-G27-G23-G29-G34+G14 -> 2402469.1 | H35: =H11-H13-H27-H23-H29-H34+H14 -> 2450518.5 | I35: =I11-I13-I27-I23-I29-I34+I14 -> 2499528.9 | J35: =J11-J13-J27-J23-J29-J34+J14 -> 2180147.8 | K35: =K11-K13-K27-K23-K29-K34+K14 -> 1618962.1 | ... AG35: =AG11-AG13-AG27-AG23-AG29-AG34+AG14 -> 16624846
A36: Cumulative equity cash | C36: =0+C35 -> -11426286 | D36: =C36+D35 -> -9086765.2 | E36: =D36+E35 -> -6777586.9 | F36: =E36+F35 -> -4422225 | G36: =F36+G35 -> -2019755.8 | H36: =G36+H35 -> 430762.71 | I36: =H36+I35 -> 2930291.6 | J36: =I36+J35 -> 5110439.4 | K36: =J36+K35 -> 6729401.4 | ... AG36: =AF36+AG35 -> 94816757
